Workbook

Sheet Sheet
N1: BASE INSS | P1: BASE GERAL FOLHA | R1: VALOR SALARIO FAMILIA | S1: 20% PATRONAL | T1: 5,8% TERCEIROS | U1: RAT AJUSTADO 3x FAP 1,0312 | W1: VALOR GUIA LANÇAMENTO INSS | X1: IRRF FOLHA
N2: PROLABORE | O2: 8475.55 | P2: =P4+O2 -> 339404.33 | Q2: =eSocial!XEI17 -> 339404.33 | R2: 87.8 | T2: =eSocial!XEK29 -> 19193.84 | U2: 3 | V2: 1.0312 | W2: =S6+T3+V4+P10-R2 -> 126592.04 | X2: 4632.58
P3: BASE TOTAL FOLHA | T3: =P4*0.058 -> 19193.869 | V3: =U2*V2 -> 3.0936
N4: =N11 -> 320213.14 | O4: 10715.64 | P4: =O4+N4 -> 330928.78 | S4: =O2*0.2 -> 1695.11 | T4: =eSocial!XEI28 -> 1695.11 | V4: =P4*(V3/100) -> 10237.613 | W4: =eSocial!XEI34 -> 10237.61 | X4: VALOR GUIA eCAC | Y4: =W2+X2 -> 131224.62
S5: =P4*0.2 -> 66185.756 | T5: =eSocial!XEI27 -> 66185.75
P6: 27471.49 | S6: =SUM(S4:S5) -> 67880.866
P7: 160.11
P8: 932.31 | Q8: =P6+P8 -> 28403.8 | S8: 5069.08 | T8: 124896.91 | U8: =T8+S4 -> 126592.02
P9: 803.58 | S9: 1695.13
P10: =SUM(P6:P9) -> 29367.49 | Q10: =eSocial!XEJ19 -> 29367.49
N11: =N150 -> 320213.14 | O11: =O150 -> 10715.64 | P11: =P150 -> 28403.8 | Q11: =Q150 -> 803.58 | R11: =R150 -> 160.11 | S11: =S151 -> 66185.756 | T11: =T151 -> 9927.8634 | U11: =U151 -> 19193.869 | V11: =V151 -> 124587.18 | W11: =W151 -> 326639.36 | X11: =X151 -> 2049.33 | Y11: =Y151 -> 4632.58 | Z11: =Z151 -> 0 | AA11: =AA151 -> 0
A12: NOME | B12: CCUSTO | C12: CODSITUACAO | D12: CODTIPO | E12: BASEFGTS | F12: BASEFGTSAVPREVIO | H12: BASEFGTS13AVPREVIO | I12: BASEFGTS13 | J12: FGTS | K12: FGTS_AVISO | L12: FGTS13_AVISO | M12: FGTS13 | N12: BASEINSS | O12: BASEINSS13 | P12: INSS | Q12: INSS13 | R12: INSSFERIAS | S12: INSS EMPRESA | T12: INSS RAT AJUSTADO | U12: INSS TERCEIROS | V12: TOTAL GUA | W12: BASEIRRF | X12: BASEIRRFFERIAS | Y12: IRRF | Z12: IRRF13 | AA12: IRRFFERIAS | AD12: Nome | AE12: Governo - Base INSS | AF12: Governo - Base INSS - 13° Salário | AG12: Governo - Valor INSS | AH12: Governo - Valor INSS - 13° Salário | AI12: CONFERE BASE FGTS | AJ12: CONFERE VALOR FGTS | AK12: Nome Trabalhador | AL12: Base Remuneracao Total | AM12: Valor FGTS na Guia
A13: ADNNY DA SILVA PITANGA | B13: BR - 060/GO - Rio Verde GO | C13: D | D13: N | E13: 1467.94 | F13: 613.89 | H13: 0 | I13: 602.59 | J13: 117.4352 | K13: 49.1112 | L13: 0 | M13: 48.2072 | N13: 1467.94 | O13: 602.59 | P13: 110.09 | Q13: 45.19 | R13: 0 | S13: 414.106 | T13: 62.1159 | U13: 120.09074 | V13: 751.59264 | W13: 1467.94 | X13: 0 | Y13: 0 | Z13: 0 | AA13: 0 | AB13: =(N13+O13)-(AE13+AF13) -> 0 | AC13: =(P13+Q13)-(AG13+AH13) -> 0 | AD13: ADNNY DA SILVA PITANGA | AE13: 1467.94 | AF13: 602.59 | AG13: 110.09 | AH13: 45.19 | AI13: =(E13+F13+H13+I13)-AL13 -> 2684.42 | AJ13: =(J13+K13+L13+M13)-AM13 -> 214.7536
A14: ADRYAN ANDRADE ESPIRITO SANTO | B14: BR - 060/GO - Rio Verde GO | C14: D | D14: N | E14: 1429.82 | F14: 612.64 | H14: 0 | I14: 601.71 | J14: 114.3856 | K14: 49.0112 | L14: 0 | M14: 48.1368 | N14: 1429.82 | O14: 601.71 | P14: 107.23 | Q14: 45.12 | R14: 0 | S14: 406.306 | T14: 60.9459 | U14: 117.82874 | V14: 737.43064 | W14: 1429.82 | X14: 0 | Y14: 0 | Z14: 0 | AA14: 0 | AB14: =(N14+O14)-(AE14+AF14) -> 0 | AC14: =(P14+Q14)-(AG14+AH14) -> 0 | AD14: ADRYAN ANDRADE ESPIRITO SANTO | AE14: 1429.82 | AF14: 601.71 | AG14: 107.23 | AH14: 45.12 | AI14: =(E14+F14+H14+I14)-AL14 -> 2644.17 | AJ14: =(J14+K14+L14+M14)-AM14 -> 211.5336
A15: ALDECIR DA SILVA | B15: BR-463/MS - Dourados | C15: A | D15: N | E15: 1981.3 | F15: 0 | H15: 0 | I15: 0 | J15: 158.504 | K15: 0 | L15: 0 | M15: 0 | N15: 1981.3 | O15: 0 | P15: 153.99 | Q15: 0 | R15: 0 | S15: 396.26 | T15: 59.439 | U15: 114.9154 | V15: 724.6044 | W15: 1981.3 | X15: 0 | Y15: 0 | Z15: 0 | AA15: 0 | AB15: =(N15+O15)-(AE15+AF15) -> 0 | AC15: =(P15+Q15)-(AG15+AH15) -> 0 | AD15: ALDECIR DA SILVA | AE15: 1981.3 | AF15: 0 | AG15: 153.99 | AH15: 0 | AI15: =(E15+F15+H15+I15)-AL15 -> 0 | AJ15: =(J15+K15+L15+M15)-AM15 -> 0.004 | AK15: ALDECIR DA SILVA | AL15: 1981.3 | AM15: 158.5
A16: ALDO PLACIDO DE ESPIRITO SANTO | B16: Oficina | C16: A | D16: N | E16: 3353.75 | F16: 0 | H16: 0 | I16: 0 | J16: 268.3 | K16: 0 | L16: 0 | M16: 0 | N16: 3353.75 | O16: 0 | P16: 291.03 | Q16: 0 | R16: 0 | S16: 670.75 | T16: 100.6125 | U16: 194.5175 | V16: 1256.91 | W16: 3353.75 | X16: 0 | Y16: 0 | Z16: 0 | AA16: 0 | AB16: =(N16+O16)-(AE16+AF16) -> 0 | AC16: =(P16+Q16)-(AG16+AH16) -> 0 | AD16: ALDO PLACIDO DE ESPIRITO SANTO | AE16: 3353.75 | AF16: 0 | AG16: 291.03 | AH16: 0 | AI16: =(E16+F16+H16+I16)-AL16 -> 0 | AJ16: =(J16+K16+L16+M16)-AM16 -> 0 | AK16: ALDO PLACIDO DE ESPIRITO SANTO | AL16: 3353.75 | AM16: 268.3
A17: ALESSANDRO OMIDO DA SILVA | B17: Oficina | C17: A | D17: N | E17: 4571.03 | F17: 0 | H17: 0 | I17: 0 | J17: 365.6824 | K17: 0 | L17: 0 | M17: 0 | N17: 4571.03 | O17: 0 | P17: 441.44 | Q17: 0 | R17: 0 | S17: 914.206 | T17: 137.1309 | U17: 265.11974 | V17: 1757.8966 | W17: 4571.03 | X17: 0 | Y17: 0 | Z17: 0 | AA17: 0 | AB17: =(N17+O17)-(AE17+AF17) -> 0 | AC17: =(P17+Q17)-(AG17+AH17) -> 0 | AD17: ALESSANDRO OMIDO DA SILVA | AE17: 4571.03 | AF17: 0 | AG17: 441.44 | AH17: 0 | AI17: =(E17+F17+H17+I17)-AL17 -> 0 | AJ17: =(J17+K17+L17+M17)-AM17 -> 0.0024 | AK17: ALESSANDRO OMIDO DA SILVA | AL17: 4571.03 | AM17: 365.68
A18: ALISSON ALVES DA CRUZ | B18: BR-376/MS - Nova Andradina / Ivinhema | C18: A | D18: N | E18: 1947.01 | F18: 0 | H18: 0 | I18: 0 | J18: 155.7608 | K18: 0 | L18: 0 | M18: 0 | N18: 1947.01 | O18: 0 | P18: 150.91 | Q18: 0 | R18: 0 | S18: 389.402 | T18: 58.4103 | U18: 112.92658 | V18: 711.64888 | W18: 1947.01 | X18: 0 | Y18: 0 | Z18: 0 | AA18: 0 | AB18: =(N18+O18)-(AE18+AF18) -> 0 | AC18: =(P18+Q18)-(AG18+AH18) -> 0 | AD18: ALISSON ALVES DA CRUZ | AE18: 1947.01 | AF18: 0 | AG18: 150.91 | AH18: 0 | AI18: =(E18+F18+H18+I18)-AL18 -> 0 | AJ18: =(J18+K18+L18+M18)-AM18 -> 0.0008 | AK18: ALISSON ALVES DA CRUZ | AL18: 1947.01 | AM18: 155.76
A19: ALOIR DE SOUZA VIANA | B19: BR - 262/MS - Miranda - Guaicurus MS | C19: D | D19: N | E19: 987.59 | F19: 2511.45 | H19: 184.63 | I19: 553.87 | J19: 79.0072 | K19: 200.916 | L19: 14.7704 | M19: 44.3096 | N19: 987.59 | O19: 738.5 | P19: 74.06 | Q19: 55.38 | R19: 0 | S19: 345.218 | T19: 51.7827 | U19: 100.11322 | V19: 626.55392 | W19: 987.59 | X19: 0 | Y19: 0 | Z19: 0 | AA19: 0 | AB19: =(N19+O19)-(AE19+AF19) -> 0 | AC19: =(P19+Q19)-(AG19+AH19) -> 0 | AD19: ALOIR DE SOUZA VIANA | AE19: 987.59 | AF19: 738.5 | AG19: 74.06 | AH19: 55.38 | AI19: =(E19+F19+H19+I19)-AL19 -> 4237.54 | AJ19: =(J19+K19+L19+M19)-AM19 -> 339.0032
A20: ANDERSEN GUASSACE RODRIGUES | B20: BR-262 e 359/MS - Corumbá - 2º Contrato | C20: D | D20: N | E20: 196.14 | F20: 0 | H20: 0 | I20: 0 | J20: 15.6912 | K20: 0 | L20: 0 | M20: 0 | N20: 196.14 | O20: 0 | P20: 14.71 | Q20: 0 | R20: 0 | S20: 39.228 | T20: 5.8842 | U20: 11.37612 | V20: 71.19832 | W20: 196.14 | X20: 0 | Y20: 0 | Z20: 0 | AA20: 0 | AB20: =(N20+O20)-(AE20+AF20) -> 0 | AC20: =(P20+Q20)-(AG20+AH20) -> 0 | AD20: ANDERSEN GUASSACE RODRIGUES | AE20: 196.14 | AF20: 0 | AG20: 14.71 | AH20: 0 | AI20: =(E20+F20+H20+I20)-AL20 -> 0 | AJ20: =(J20+K20+L20+M20)-AM20 -> 0.0012 | AK20: ANDERSEN GUASSACE RODRIGUES | AL20: 196.14 | AM20: 15.69
A21: ANDRE AUGUSTO CAVALHEIRO DA SILVA | B21: BR - 267/MS - Nova Alvorada MS - 2º Contrato | C21: A | D21: N | E21: 2012.88 | F21: 0 | H21: 0 | I21: 0 | J21: 161.0304 | K21: 0 | L21: 0 | M21: 0 | N21: 2012.88 | O21: 0 | P21: 156.83 | Q21: 0 | R21: 0 | S21: 402.576 | T21: 60.3864 | U21: 116.74704 | V21: 736.53944 | W21: 2012.88 | X21: 0 | Y21: 0 | Z21: 0 | AA21: 0 | AB21: =(N21+O21)-(AE21+AF21) -> 0 | AC21: =(P21+Q21)-(AG21+AH21) -> 0 | AD21: ANDRE AUGUSTO CAVALHEIRO DA SILVA | AE21: 2012.88 | AF21: 0 | AG21: 156.83 | AH21: 0 | AI21: =(E21+F21+H21+I21)-AL21 -> 0 | AJ21: =(J21+K21+L21+M21)-AM21 -> 0.0004 | AK21: ANDRE AUGUSTO CAVALHEIRO DA SILVA | AL21: 2012.88 | AM21: 161.03
A22: ANDREIA PERPETUA MORENO | B22: Oficina | C22: A | D22: N | E22: 2700 | F22: 0 | H22: 0 | I22: 0 | J22: 216 | K22: 0 | L22: 0 | M22: 0 | N22: 2700 | O22: 0 | P22: 218.68 | Q22: 0 | R22: 0 | S22: 540 | T22: 81 | U22: 156.6 | V22: 996.28 | W22: 2700 | X22: 0 | Y22: 0 | Z22: 0 | AA22: 0 | AB22: =(N22+O22)-(AE22+AF22) -> 0 | AC22: =(P22+Q22)-(AG22+AH22) -> 0 | AD22: ANDREIA PERPETUA MORENO | AE22: 2700 | AF22: 0 | AG22: 218.68 | AH22: 0 | AI22: =(E22+F22+H22+I22)-AL22 -> 0 | AJ22: =(J22+K22+L22+M22)-AM22 -> 0 | AK22: ANDREIA PERPETUA MORENO | AL22: 2700 | AM22: 216
A23: ANTONIO MARCOS DE LIMA | B23: Oficina | C23: A | D23: N | E23: 3798.32 | F23: 0 | H23: 0 | I23: 0 | J23: 303.8656 | K23: 0 | L23: 0 | M23: 0 | N23: 3798.32 | O23: 0 | P23: 344.38 | Q23: 0 | R23: 0 | S23: 759.664 | T23: 113.9496 | U23: 220.30256 | V23: 1438.2962 | W23: 3798.32 | X23: 0 | Y23: 0 | Z23: 0 | AA23: 0 | AB23: =(N23+O23)-(AE23+AF23) -> 0 | AC23: =(P23+Q23)-(AG23+AH23) -> 0 | AD23: ANTONIO MARCOS DE LIMA | AE23: 3798.32 | AF23: 0 | AG23: 344.38 | AH23: 0 | AI23: =(E23+F23+H23+I23)-AL23 -> 0 | AJ23: =(J23+K23+L23+M23)-AM23 -> 0.0056 | AK23: ANTONIO MARCOS DE LIMA | AL23: 3798.32 | AM23: 303.86
A24: ANTONIO MARCOS DOS SANTOS MOREIRA | B24: Restaura MS180 - Juti MS | C24: A | D24: N | E24: 2161.49 | F24: 0 | H24: 0 | I24: 0 | J24: 172.9192 | K24: 0 | L24: 0 | M24: 0 | N24: 2161.49 | O24: 0 | P24: 170.21 | Q24: 0 | R24: 0 | S24: 432.298 | T24: 64.8447 | U24: 125.36642 | V24: 792.71912 | W24: 2161.49 | X24: 0 | Y24: 0 | Z24: 0 | AA24: 0 | AB24: =(N24+O24)-(AE24+AF24) -> 0 | AC24: =(P24+Q24)-(AG24+AH24) -> 0 | AD24: ANTONIO MARCOS DOS SANTOS MOREIRA | AE24: 2161.49 | AF24: 0 | AG24: 170.21 | AH24: 0 | AI24: =(E24+F24+H24+I24)-AL24 -> 0 | AJ24: =(J24+K24+L24+M24)-AM24 -> 0.0092 | AK24: ANTONIO MARCOS DOS SANTOS MOREIRA | AL24: 2161.49 | AM24: 172.91
A25: ARNALDO SALLES GUIMARAES | B25: BR-060/MS - Jardim - 2º Contrato | C25: A | D25: N | E25: 3560.44 | F25: 0 | H25: 0 | I25: 0 | J25: 284.8352 | K25: 0 | L25: 0 | M25: 0 | N25: 3560.44 | O25: 0 | P25: 315.84 | Q25: 0 | R25: 0 | S25: 712.088 | T25: 106.8132 | U25: 206.50552 | V25: 1341.2467 | W25: 3560.44 | X25: 0 | Y25: 0 | Z25: 0 | AA25: 0 | AB25: =(N25+O25)-(AE25+AF25) -> 0 | AC25: =(P25+Q25)-(AG25+AH25) -> 0 | AD25: ARNALDO SALLES GUIMARAES | AE25: 3560.44 | AF25: 0 | AG25: 315.84 | AH25: 0 | AI25: =(E25+F25+H25+I25)-AL25 -> 0 | AJ25: =(J25+K25+L25+M25)-AM25 -> 0.0052 | AK25: ARNALDO SALLES GUIMARAES | AL25: 3560.44 | AM25: 284.83
A26: CANDELARIO GARCIA MELGAR | B26: BR-262 e 359/MS - Corumbá - 2º Contrato | C26: A | D26: N | E26: 1606.37 | F26: 0 | H26: 0 | I26: 0 | J26: 128.5096 | K26: 0 | L26: 0 | M26: 0 | N26: 1606.37 | O26: 0 | P26: 120.47 | Q26: 0 | R26: 0 | S26: 321.274 | T26: 48.1911 | U26: 93.16946 | V26: 583.10456 | W26: 1606.37 | X26: 0 | Y26: 0 | Z26: 0 | AA26: 0 | AB26: =(N26+O26)-(AE26+AF26) -> 0 | AC26: =(P26+Q26)-(AG26+AH26) -> 0 | AD26: CANDELARIO GARCIA MELGAR | AE26: 1606.37 | AF26: 0 | AG26: 120.47 | AH26: 0 | AI26: =(E26+F26+H26+I26)-AL26 -> 0 | AJ26: =(J26+K26+L26+M26)-AM26 -> 0.0096 | AK26: CANDELARIO GARCIA MELGAR | AL26: 1606.37 | AM26: 128.5
A27: CARLA CRISTINA GAMBATTI | B27: Financeiro | C27: A | D27: N | E27: 2500 | F27: 0 | H27: 0 | I27: 0 | J27: 200 | K27: 0 | L27: 0 | M27: 0 | N27: 2500 | O27: 0 | P27: 200.68 | Q27: 0 | R27: 0 | S27: 500 | T27: 75 | U27: 145 | V27: 920.68 | W27: 2500 | X27: 0 | Y27: 0 | Z27: 0 | AA27: 0 | AB27: =(N27+O27)-(AE27+AF27) -> 0 | AC27: =(P27+Q27)-(AG27+AH27) -> 0 | AD27: CARLA CRISTINA GAMBATTI | AE27: 2500 | AF27: 0 | AG27: 200.68 | AH27: 0 | AI27: =(E27+F27+H27+I27)-AL27 -> 0 | AJ27: =(J27+K27+L27+M27)-AM27 -> 0 | AK27: CARLA CRISTINA GAMBATTI | AL27: 2500 | AM27: 200
A28: CARLOS DONIZETI BOTARO | B28: BR - 060/MS Contorno Campo Grande 2º Contrato | C28: A | D28: N | E28: 7907.32 | F28: 0 | H28: 0 | I28: 0 | J28: 632.5856 | K28: 0 | L28: 0 | M28: 0 | N28: 7907.32 | O28: 0 | P28: 908.52 | Q28: 0 | R28: 0 | S28: 1581.464 | T28: 237.2196 | U28: 458.62456 | V28: 3185.8282 | W28: 7907.32 | X28: 0 | Y28: 963.8 | Z28: 0 | AA28: 0 | AB28: =(N28+O28)-(AE28+AF28) -> 0 | AC28: =(P28+Q28)-(AG28+AH28) -> 0 | AD28: CARLOS DONIZETI BOTARO | AE28: 7907.32 | AF28: 0 | AG28: 908.52 | AH28: 0 | AI28: =(E28+F28+H28+I28)-AL28 -> 0 | AJ28: =(J28+K28+L28+M28)-AM28 -> 0.0056 | AK28: CARLOS DONIZETI BOTARO | AL28: 7907.32 | AM28: 632.58
A29: CARLOS HENRIQUE TREVISAN BARBOSA | B29: BR - 359/MS - Coxim MS | C29: D | D29: N | E29: 142.71 | F29: 0 | H29: 0 | I29: 0 | J29: 11.4168 | K29: 0 | L29: 0 | M29: 0 | N29: 142.71 | O29: 0 | P29: 10.7 | Q29: 0 | R29: 0 | S29: 28.542 | T29: 4.2813 | U29: 8.27718 | V29: 51.80048 | W29: 142.71 | X29: 0 | Y29: 0 | Z29: 0 | AA29: 0 | AB29: =(N29+O29)-(AE29+AF29) -> 0 | AC29: =(P29+Q29)-(AG29+AH29) -> 0 | AD29: CARLOS HENRIQUE TREVISAN BARBOSA | AE29: 142.71 | AF29: 0 | AG29: 10.7 | AH29: 0 | AI29: =(E29+F29+H29+I29)-AL29 -> 0 | AJ29: =(J29+K29+L29+M29)-AM29 -> 0.0068 | AK29: CARLOS HENRIQUE TREVISAN BARBOSA | AL29: 142.71 | AM29: 11.41
A30: CARLOS MORAES | B30: BR-060/MS - Jardim - 2º Contrato | C30: A | D30: N | E30: 1990.05 | F30: 0 | H30: 0 | I30: 0 | J30: 159.204 | K30: 0 | L30: 0 | M30: 0 | N30: 1990.05 | O30: 0 | P30: 154.78 | Q30: 0 | R30: 0 | S30: 398.01 | T30: 59.7015 | U30: 115.4229 | V30: 727.9144 | W30: 1990.05 | X30: 0 | Y30: 0 | Z30: 0 | AA30: 0 | AB30: =(N30+O30)-(AE30+AF30) -> 0 | AC30: =(P30+Q30)-(AG30+AH30) -> 0 | AD30: CARLOS MORAES | AE30: 1990.05 | AF30: 0 | AG30: 154.78 | AH30: 0 | AI30: =(E30+F30+H30+I30)-AL30 -> 0 | AJ30: =(J30+K30+L30+M30)-AM30 -> 0.004 | AK30: CARLOS MORAES | AL30: 1990.05 | AM30: 159.2
A31: CHARLES FRANCO RODRIGUES | B31: Restaura MS180 - Juti MS | C31: A | D31: N | E31: 2068.35 | F31: 0 | H31: 0 | I31: 0 | J31: 165.468 | K31: 0 | L31: 0 | M31: 0 | N31: 2068.35 | O31: 0 | P31: 161.83 | Q31: 0 | R31: 0 | S31: 413.67 | T31: 62.0505 | U31: 119.9643 | V31: 757.5148 | W31: 2068.35 | X31: 0 | Y31: 0 | Z31: 0 | AA31: 0 | AB31: =(N31+O31)-(AE31+AF31) -> 0 | AC31: =(P31+Q31)-(AG31+AH31) -> 0 | AD31: CHARLES FRANCO RODRIGUES | AE31: 2068.35 | AF31: 0 | AG31: 161.83 | AH31: 0 | AI31: =(E31+F31+H31+I31)-AL31 -> 0 | AJ31: =(J31+K31+L31+M31)-AM31 -> 0.008 | AK31: CHARLES FRANCO RODRIGUES | AL31: 2068.35 | AM31: 165.46
... A41: EDER AUGUSTO TREVISAN BARBOSA | B41: BR - 060/MS - Sidrolândia MS | C41: A | D41: N | E41: 3013.01 | F41: 0 | H41: 0 | I41: 0 | J41: 241.0408 | K41: 0 | L41: 0 | M41: 0 | N41: 3013.01 | O41: 0 | P41: 250.15 | Q41: 0 | R41: 0 | S41: 602.602 | T41: 90.3903 | U41: 174.75458 | V41: 1117.8969 | W41: 3013.01 | X41: 0 | Y41: 0 | Z41: 0 | AA41: 0 | AB41: =(N41+O41)-(AE41+AF41) -> 0 | AC41: =(P41+Q41)-(AG41+AH41) -> 0 | AD41: EDER AUGUSTO TREVISAN BARBOSA | AE41: 3013.01 | AF41: 0 | AG41: 250.15 | AH41: 0 | AI41: =(E41+F41+H41+I41)-AL41 -> 0 | AJ41: =(J41+K41+L41+M41)-AM41 -> 0.0008 | AK41: EDER AUGUSTO TREVISAN BARBOSA | AL41: 3013.01 | AM41: 241.04
A42: EDIVANIO RODRIGUES DA SILVA | B42: BR - 060/GO - Rio Verde GO | C42: D | D42: N | E42: 2706.69 | F42: 0 | H42: 0 | I42: 610.23 | J42: 216.5352 | K42: 0 | L42: 0 | M42: 48.8184 | N42: 2706.69 | O42: 610.23 | P42: 219.28 | Q42: 45.76 | R42: 0 | S42: 663.384 | T42: 99.5076 | U42: 192.38136 | V42: 1220.313 | W42: 2706.69 | X42: 0 | Y42: 0 | Z42: 0 | AA42: 0 | AB42: =(N42+O42)-(AE42+AF42) -> 0 | AC42: =(P42+Q42)-(AG42+AH42) -> 0 | AD42: EDIVANIO RODRIGUES DA SILVA | AE42: 2706.69 | AF42: 610.23 | AG42: 219.28 | AH42: 45.76 | AI42: =(E42+F42+H42+I42)-AL42 -> 3316.92 | AJ42: =(J42+K42+L42+M42)-AM42 -> 265.3536
A43: EDUARDO BATISTA MOREIRA | B43: Restaura MS180 - Juti MS | C43: A | D43: N | E43: 644.03 | F43: 0 | H43: 0 | I43: 0 | J43: 51.5224 | K43: 0 | L43: 0 | M43: 0 | N43: 644.03 | O43: 0 | P43: 48.3 | Q43: 0 | R43: 0 | S43: 128.806 | T43: 19.3209 | U43: 37.35374 | V43: 233.78064 | W43: 644.03 | X43: 0 | Y43: 0 | Z43: 0 | AA43: 0 | AB43: =(N43+O43)-(AE43+AF43) -> 0 | AC43: =(P43+Q43)-(AG43+AH43) -> 0 | AD43: EDUARDO BATISTA MOREIRA | AE43: 644.03 | AF43: 0 | AG43: 48.3 | AH43: 0 | AI43: =(E43+F43+H43+I43)-AL43 -> 0 | AJ43: =(J43+K43+L43+M43)-AM43 -> 0.0024 | AK43: EDUARDO BATISTA MOREIRA | AL43: 644.03 | AM43: 51.52
A44: ELERRANDRO DUTRA SOUSA | B44: BR - 060/GO - Rio Verde GO | C44: D | D44: N | E44: 1551.26 | F44: 908.66 | H44: 0 | I44: 611.41 | J44: 124.1008 | K44: 72.6928 | L44: 0 | M44: 48.9128 | N44: 1551.26 | O44: 611.41 | P44: 116.34 | Q44: 45.85 | R44: 0 | S44: 432.534 | T44: 64.8801 | U44: 125.43486 | V44: 785.03896 | W44: 1551.26 | X44: 0 | Y44: 0 | Z44: 0 | AA44: 0 | AB44: =(N44+O44)-(AE44+AF44) -> 0 | AC44: =(P44+Q44)-(AG44+AH44) -> 0 | AD44: ELERRANDRO DUTRA SOUSA | AE44: 1551.26 | AF44: 611.41 | AG44: 116.34 | AH44: 45.85 | AI44: =(E44+F44+H44+I44)-AL44 -> 3071.33 | AJ44: =(J44+K44+L44+M44)-AM44 -> 245.7064
A45: ELIAQUIM SANTOS MACHADO | B45: BR - 060/GO - Rio Verde GO | C45: D | D45: N | E45: 1539.48 | F45: 618.45 | H45: 0 | I45: 606.71 | J45: 123.1584 | K45: 49.476 | L45: 0 | M45: 48.5368 | N45: 1539.48 | O45: 606.71 | P45: 115.46 | Q45: 45.5 | R45: 0 | S45: 429.238 | T45: 64.3857 | U45: 124.47902 | V45: 779.06272 | W45: 1539.48 | X45: 0 | Y45: 0 | Z45: 0 | AA45: 0 | AB45: =(N45+O45)-(AE45+AF45) -> 0 | AC45: =(P45+Q45)-(AG45+AH45) -> 0 | AD45: ELIAQUIM SANTOS MACHADO | AE45: 1539.48 | AF45: 606.71 | AG45: 115.46 | AH45: 45.5 | AI45: =(E45+F45+H45+I45)-AL45 -> 2764.64 | AJ45: =(J45+K45+L45+M45)-AM45 -> 221.1712
A46: ELIAS FREITAS DE MIRANDA | B46: BR - 359/MS - Coxim MS | C46: A | D46: N | E46: 2024.69 | F46: 0 | H46: 0 | I46: 0 | J46: 161.9752 | K46: 0 | L46: 0 | M46: 0 | N46: 2024.69 | O46: 0 | P46: 157.9 | Q46: 0 | R46: 0 | S46: 404.938 | T46: 60.7407 | U46: 117.43202 | V46: 741.01072 | W46: 2024.69 | X46: 0 | Y46: 0 | Z46: 0 | AA46: 0 | AB46: =(N46+O46)-(AE46+AF46) -> 0 | AC46: =(P46+Q46)-(AG46+AH46) -> 0 | AD46: ELIAS FREITAS DE MIRANDA | AE46: 2024.69 | AF46: 0 | AG46: 157.9 | AH46: 0 | AI46: =(E46+F46+H46+I46)-AL46 -> 0 | AJ46: =(J46+K46+L46+M46)-AM46 -> 0.0052 | AK46: ELIAS FREITAS DE MIRANDA | AL46: 2024.69 | AM46: 161.97
A47: ELIUDI DANIEL | B47: BR-463/MS - Dourados | C47: A | D47: N | E47: 1987.4 | F47: 0 | H47: 0 | I47: 0 | J47: 158.992 | K47: 0 | L47: 0 | M47: 0 | N47: 1987.4 | O47: 0 | P47: 154.54 | Q47: 0 | R47: 0 | S47: 397.48 | T47: 59.622 | U47: 115.2692 | V47: 726.9112 | W47: 1987.4 | X47: 0 | Y47: 0 | Z47: 0 | AA47: 0 | AB47: =(N47+O47)-(AE47+AF47) -> 0 | AC47: =(P47+Q47)-(AG47+AH47) -> 0 | AD47: ELIUDI DANIEL | AE47: 1987.4 | AF47: 0 | AG47: 154.54 | AH47: 0 | AI47: =(E47+F47+H47+I47)-AL47 -> 0 | AJ47: =(J47+K47+L47+M47)-AM47 -> 0.002 | AK47: ELIUDI DANIEL | AL47: 1987.4 | AM47: 158.99
A48: ELIZABETE DUARTE DA SILVA | B48: Restaura MS180 - Juti MS | C48: A | D48: N | E48: 1067.17 | F48: 0 | H48: 0 | I48: 0 | J48: 85.3736 | K48: 0 | L48: 0 | M48: 0 | N48: 1067.17 | O48: 0 | P48: 80.03 | Q48: 0 | R48: 0 | S48: 213.434 | T48: 32.0151 | U48: 61.89586 | V48: 319.83496 | W48: 1067.17 | X48: 0 | Y48: 0 | Z48: 0 | AA48: 0 | AB48: =(N48+O48)-(AE48+AF48) -> 0 | AC48: =(P48+Q48)-(AG48+AH48) -> 0 | AD48: ELIZABETE DUARTE DA SILVA | AE48: 1067.17 | AF48: 0 | AG48: 80.03 | AH48: 0 | AI48: =(E48+F48+H48+I48)-AL48 -> 0 | AJ48: =(J48+K48+L48+M48)-AM48 -> 0.0036 | AK48: ELIZABETE DUARTE DA SILVA | AL48: 1067.17 | AM48: 85.37
A49: ELTON DA SILVA FONSECA | B49: Restaura MS180 - Juti MS | C49: A | D49: N | E49: 5600.47 | F49: 0 | H49: 0 | I49: 0 | J49: 448.0376 | K49: 0 | L49: 0 | M49: 0 | N49: 5600.47 | O49: 0 | P49: 585.56 | Q49: 0 | R49: 0 | S49: 1120.094 | T49: 168.0141 | U49: 324.82726 | V49: 2198.4954 | W49: 5600.47 | X49: 0 | Y49: 134.6 | Z49: 0 | AA49: 0 | AB49: =(N49+O49)-(AE49+AF49) -> 0 | AC49: =(P49+Q49)-(AG49+AH49) -> 0 | AD49: ELTON DA SILVA FONSECA | AE49: 5600.47 | AF49: 0 | AG49: 585.56 | AH49: 0 | AI49: =(E49+F49+H49+I49)-AL49 -> 0 | AJ49: =(J49+K49+L49+M49)-AM49 -> 0.0076 | AK49: ELTON DA SILVA FONSECA | AL49: 5600.47 | AM49: 448.03
...

Sheet Emprestimos
L1: 9724.89
L2: 4424.03
L3: 1349.19
L4: 276.16
L5: 143.02
D7: NOME | E7: CODSITUACAO | F7: 5 | L7: =SUM(L1:L6) -> 15917.29
A8: ADNNY DA SILVA PITANGA | B8: 522.6 | C8: =B8-F8 -> 0 | D8: ADNNY DA SILVA PITANGA | E8: D | F8: 522.6
A9: Aloir de Souza Viana | B9: 558.83 | C9: =B9-F9 -> 0 | D9: ALOIR DE SOUZA VIANA | E9: D | F9: 558.83
A10: Arnaldo Salles Guimaraes | B10: 979.3 | C10: =B10-F10 -> 0 | D10: ARNALDO SALLES GUIMARAES | E10: A | F10: 979.3
A11: Daglos Loveira Vaz | B11: 371.63 | C11: =B11-F11 -> 0 | D11: DAGLOS LOVEIRA VAZ | E11: A | F11: 371.63
A12: Daniel Gonzaga Souza | B12: 288.1 | C12: =B12-F12 -> 0 | D12: DANIEL GONZAGA SOUZA | E12: D | F12: 288.1
A13: ELIAQUIM SANTOS MACHADO | B13: 553.93 | C13: =B13-F13 -> 0 | D13: ELIAQUIM SANTOS MACHADO | E13: D | F13: 553.93
A14: Evaldo Benedito Constantino | B14: 650.13 | C14: =B14-F14 -> 0 | D14: EVALDO BENEDITO CONSTANTINO | E14: A | F14: 650.13
A15: Fabio Velasquez Galeano | B15: 485.58 | C15: =B15-F15 -> 0 | D15: FABIO VELASQUEZ GALEANO | E15: A | F15: 485.58
A16: FILIPE DOS SANTOS | B16: 577.04 | C16: =B16-F16 -> 0 | D16: FILIPE DOS SANTOS | E16: D | F16: 577.04
A17: Flavio Carlos de Souza Ortega | B17: 599.43 | C17: =B17-F17 -> 0 | D17: FLAVIO CARLOS DE SOUZA ORTEGA | E17: A | F17: 599.43
A18: FRANCISCO DE ASSIS ANDRADE NETO | B18: 909.99 | C18: =B18-F18 -> 0 | D18: FRANCISCO DE ASSIS ANDRADE NETO | E18: D | F18: 909.99
A19: Geferson Escot Ataide Thomaz | B19: 949.23 | C19: =B19-F19 -> 0 | D19: GEFERSON ESCOT ATAIDE THOMAZ | E19: A | F19: 949.23
... A26: Jose Junior Vieira da Silva | B26: 435.25 | C26: =B26-F26 -> 0 | D26: JOSE JUNIOR VIEIRA DA SILVA | E26: A | F26: 435.25
C27: =B27-F27 -> -114.63 | D27: JOSE PETRUCIO JACINTO DA SILVA | E27: D | F27: 114.63
A28: Luciano Farias Ribeiro | B28: 165.35 | C28: =B28-F28 -> 0 | D28: LUCIANO FARIAS RIBEIRO | E28: A | F28: 165.35
A29: Luiz Pedro dos Santos | B29: 293.2 | C29: =B29-F29 -> 0 | D29: LUIZ PEDRO DOS SANTOS | E29: A | F29: 293.2
A30: Marcos Goncalves Pereira | B30: 217.53 | C30: =B30-F30 -> 0 | D30: MARCOS GONCALVES PEREIRA | E30: A | F30: 217.53
A31: Marcos Marciel da Silva | B31: 559.53 | C31: =B31-F31 -> 0 | D31: MARCOS MARCIEL DA SILVA | E31: A | F31: 559.53
A32: Nilson Bernal da Silva | B32: 856.98 | C32: =B32-F32 -> 0 | D32: NILSON BERNAL DA SILVA | E32: A | F32: 856.98
A33: Reginaldo da Silva Saltiva | B33: 346.18 | C33: =B33-F33 -> 0 | D33: REGINALDO DA SILVA SALTIVA | E33: A | F33: 346.18
A34: Temistocles Candido Rodrigues | B34: 400 | C34: =B34-F34 -> 0 | D34: TEMISTOCLES CANDIDO RODRIGUES | E34: A | F34: 400
A35: Ulisses Luiz Orue | B35: 264.77 | C35: =B35-F35 -> 0 | D35: ULISSES LUIZ ORUE | E35: A | F35: 264.77
A36: Wellington Martins | B36: 245.37 | C36: =B36-F36 -> 0 | D36: WELLINGTON MARTINS | E36: A | F36: 245.37
A37: Willanir da Silva | B37: 1278.77 | C37: =B37-F37 -> 0 | D37: WILLANIR DA SILVA | E37: A | F37: 1278.77
F38: 15917.29
B39: =SUM(B8:B38) -> 15802.66
B40: =B18+B16+B13+B9+B8 -> 3122.39
B42: =B39-B40 -> 12680.27 | C42: =B44-L7 -> 18810.42
B44: =SUM(B8:B40) -> 34727.71

Sheet GRRF
A1: NOME | F1: CHAPA | H1: CODTIPO | I1: FGTS QUITACAO | L1: FGTS MES ANTERIOR | N1: FGTS AVISO PREVIO | O1: FGTS ARTIGO 22 | P1: FGTS 13 SALARIO INDENIZADO | Q1: FGTS 13 Sal rescisao | S1: MÊS
A2: ADNNY DA SILVA PITANGA | F2: 00000667 | H2: N | I2: 117.43 | N2: 49.11 | O2: 1048.8 | Q2: 48.2 | R2: 1263.54 | S2: =I2+N2+P2+Q2 -> 214.74
A3: ADRYAN ANDRADE ESPIRITO SANTO | F3: 00000674 | H3: N | I3: 114.38 | N3: 49.01 | O3: 1039.8 | Q3: 48.13 | R3: 1251.32 | S3: =I3+N3+P3+Q3 -> 211.52
A4: ALOIR DE SOUZA VIANA | F4: 00000615 | H4: N | I4: 79 | N4: 200.91 | O4: 1233.41 | P4: 14.77 | Q4: 44.3 | R4: 1572.39 | S4: =I4+N4+P4+Q4 -> 338.98
A5: EDIVANIO RODRIGUES DA SILVA | F5: 00000778 | H5: N | I5: 216.53 | O5: 185.36 | Q5: 48.81 | R5: 450.7 | S5: =I5+N5+P5+Q5 -> 265.34
A6: ELERRANDRO DUTRA SOUSA | F6: 00000554 | H6: N | I6: 124.1 | N6: 72.69 | O6: 1809.59 | Q6: 48.91 | R6: 2055.29 | S6: =I6+N6+P6+Q6 -> 245.7
A7: ELIAQUIM SANTOS MACHADO | F7: 00000673 | H7: N | I7: 123.15 | N7: 49.47 | O7: 1064.92 | Q7: 48.53 | R7: 1286.07 | S7: =I7+N7+P7+Q7 -> 221.15
A8: FILIPE DOS SANTOS | F8: 00000665 | H8: N | I8: 105.09 | N8: 49.36 | O8: 1041.31 | Q8: 47.86 | R8: 1243.62 | S8: =I8+N8+P8+Q8 -> 202.31
A9: FRANCISCO DE ASSIS ANDRADE NETO | F9: 00000718 | H9: N | I9: 210.7 | N9: 69.35 | O9: 1309.11 | Q9: 74.69 | R9: 1663.85 | S9: =I9+N9+P9+Q9 -> 354.74
A10: JOSE PETRUCIO JACINTO DA SILVA | F10: 00000478 | H10: N | I10: 115.15 | L10: 150.85 | N10: 22.61 | O10: 1615.66 | Q10: 37.25 | R10: 1941.52 | S10: =I10+N10+P10+Q10 -> 175.01
A11: PEDRO HENRIQUE DE SOUSA PINHEIRO | F11: 00000650 | H11: N | I11: 185.04 | N11: 92.73 | O11: 1331.38 | Q11: 67.61 | R11: 1676.76 | S11: =I11+N11+P11+Q11 -> 345.38
A12: SAMUEL DA SILVA SOARES | F12: 00000756 | H12: N | I12: 131.8 | O12: 368.1 | Q12: 61.55 | R12: 561.45 | S12: =I12+N12+P12+Q12 -> 193.35
A13: SAMUEL DE ALMEIDA GOMES | F13: 00000719 | H13: N | I13: 198.78 | N13: 69.19 | O13: 1272.8 | Q13: 75.5 | R13: 1616.27 | S13: =I13+N13+P13+Q13 -> 343.47
I14: 1721.15 | L14: 182.19 | N14: 724.43 | O14: 13320.24 | P14: 14.77 | Q14: 651.34 | R14: 16614.12 | S14: =SUM(S2:S13) -> 3111.69

Sheet eSocial
XEH1: Contribuições Sociais do Contribuinte
XEH2: Filtro de pesquisa
XEH3: Período de Apuração:
XEH4: Número do Recibo do evento de origem:
XEH5: Razão Social
XEH6: Classificação Tributária
XEH7: Informações Complementares
XEH8: Indicativo de Cooperativa
XEH9: Indicativo de Construtora
XEH10: Indicativo de Substituição da Contribuição Previdenciária Patronal
XEH11: Indicador de tributação sobre a folha de pagamento - PIS e PASEP
XEH12: Sim Não
... XEH15: Resumo da Folha de Pagamento
XEH16: Bases de Cálculo | XEI16: Valor
XEH17: 11 - Base de cálculo da contribuição previdenciária | XEI17: 339404.33
XEH18: Contribuições do Segurado | XEI18: Valor Descontado | XEJ18: Valor Calculado
XEH19: Valor total da contribuição | XEI19: 29367.49 | XEJ19: 29367.49
XEH20: Deduções | XEI20: Valor
XEH21: Valor total do salário-família | XEI21: 87.8
XEH22: Estabelecimento 14.042.710/0001-99
XEH23: Informações consolidadas das contribuições sociais
XEH24: Codigo Receita | XEI24: Valor | XEJ24: Valor Suspenso
XEH25: 1082-01 - CP SEGURADOS - EMPREGADOS/AVULSOS | XEI25: 28435.18 | XEJ25: -
XEH26: 1099-01 - CP SEGURADOS - CONTRIBUINTES INDIVIDUAIS - 11% | XEI26: 932.31 | XEJ26: -
XEH27: 1138-01 - CP PATRONAL - EMPREGADOS/AVULSOS | XEI27: 66185.75 | XEJ27: -
XEH28: 1138-04 - CP PATRONAL - CONTRIBUINTES INDIVIDUAIS | XEI28: 1695.11 | XEJ28: -
XEH29: 1170-01 - CP TERCEIROS - SALÁRIO EDUCAÇÃO | XEI29: 8273.21 | XEJ29: - | XEK29: =XEI29+XEI30+XEI31+XEI32+XEI33 -> 19193.84
XEH30: 1176-01 - CP TERCEIROS - INCRA | XEI30: 661.85 | XEJ30: -
XEH31: 1181-01 - CP TERCEIROS - SENAI | XEI31: 3309.28 | XEJ31: -
XEH32: 1184-01 - CP TERCEIROS - SESI | XEI32: 4963.93 | XEJ32: -
XEH33: 1200-01 - CP TERCEIROS - SEBRAE | XEI33: 1985.57 | XEJ33: -
XEH34: 1646-01 - CP PATRONAL - GILRAT AJUSTADO | XEI34: 10237.61 | XEJ34: -

Sheet eCAC
A1: DÉBITOS APURADOS | E1: CRÉDITOS VINCULADOS | F1: SALDO A PAGAR
B2: Tributos/Códigos de Receita | D2: PA Débito | E2: Débito Apurado | G2: Deduções
A3: #VALUE! | G3: Salário-Família
A4: #VALUE! | B4: Total Apurado Empresa 14.042.710/0001-99 | E4: 131312.38 | F4: 87.8 | H4: 131224.58
B5: #VALUE! | C5: Total CONTRIBUIÇÃO PREVIDENCIÁRIA SEGURADOS | E5: 29367.49 | F5: 87.8 | H5: 29279.69
C6: 1082-01 CP SEGURADOS - EMPREGADOS/AVULSO | D6: 46082 | E6: 28435.18 | F6: 87.8 | H6: 28347.38
C7: 1099-01 CP SEGURADOS - CONTRIBUINTES INDIVIDUAIS - 11% | D7: 46082 | E7: 932.31 | F7: - | H7: 932.31
B8: #VALUE! | C8: Total CONTRIBUIÇÃO PREVIDENCIÁRIA PATRONAL | E8: 78118.47 | F8: - | H8: 78118.47
C9: 1138-01 CP PATRONAL - EMPREGADOS/AVULSOS | D9: 46082 | E9: 66185.75 | F9: - | H9: 66185.75
C10: 1138-04 CP PATRONAL - CONTRIBUINTES INDIVIDUAIS | D10: 46082 | E10: 1695.11 | F10: - | H10: 1695.11
C11: 1646-01 CP PATRONAL - GILRAT AJUSTADO | D11: 46082 | E11: 10237.61 | F11: - | H11: 10237.61
B12: #VALUE! | C12: Total CONTRIBUIÇÃO PARA OUTRAS ENTIDADES E FUNDOS | E12: 19193.84 | F12: - | H12: 19193.84
C13: 1170-01 CP TERCEIROS - SALÁRIO EDUCAÇÃO | D13: 46082 | E13: 8273.21 | F13: - | H13: 8273.21
C14: 1176-01 CP TERCEIROS - INCRA | D14: 46082 | E14: 661.85 | F14: - | H14: 661.85
C15: 1181-01 CP TERCEIROS - SENAI | D15: 46082 | E15: 3309.28 | F15: - | H15: 3309.28
C16: 1184-01 CP TERCEIROS - SESI | D16: 46082 | E16: 4963.93 | F16: - | H16: 4963.93
C17: 1200-01 CP TERCEIROS - SEBRAE | D17: 46082 | E17: 1985.57 | F17: - | H17: 1985.57
B18: #VALUE! | C18: Total IRRF | E18: 4632.58 | F18: - | H18: 4632.58
C19: 0561-07 IRRF - RD TRB ASSAL PAÍS/AUS NO EXT A SERV PAÍS | D19: 46082 | E19: 4632.58 | F19: - | H19: 4632.58

Sheet 1210
A1: 62 | B1: EVALDO BENEDITO CONSTANTINO | C1: 29 | D1: =A1-E1 -> 0 | E1: 62 | F1: ID1140427100000002026040616104700001
A2: 347 | B2: JOAO PAULO LUCARELO GOMES | C2: 19 | D2: =A2-E2 -> 0 | E2: 347 | F2: ID1140427100000002026040616104700000
A3: 356 | B3: JOAO IBANHES JUNIOR | C3: 491 | D3: =A3-E3 -> 0 | E3: 356 | F3: ID1140427100000002026040616104800014
A4: 454 | B4: CARLOS DONIZETI BOTARO | C4: 47 | D4: =A4-E4 -> 0 | E4: 454 | F4: ID1140427100000002026040616104700002
A5: 463 | B5: RICARDO LARANJEIRAS DE FARIAS | C5: 53 | D5: =A5-E5 -> 0 | E5: 463 | F5: ID1140427100000002026040616104700003
A6: 609 | B6: MARCOS OLIVEIRA DE CAMPOS | C6: 92 | D6: =A6-E6 -> 0 | E6: 609 | F6: ID1140427100000002026040616104700004
A7: 905 | B7: JOSE CARLOS GIMENEZ AQUINO | C7: 116 | D7: =A7-E7 -> 0 | E7: 905 | F7: ID1140427100000002026040616104700005
A8: 922 | B8: ARNALDO SALLES GUIMARAES | C8: 643 | D8: =A8-E8 -> 0 | E8: 922 | F8: ID1140427100000002026040616104900015
A9: 1111 | B9: MARCIO DE OLIVEIRA MARTINS | C9: 126 | D9: =A9-E9 -> 0 | E9: 1111 | F9: ID1140427100000002026040616104700006
A10: 1153 | B10: PAULO DE ALMEIDA | C10: 419 | D10: =A10-E10 -> 0 | E10: 1153 | F10: ID1140427100000002026040616104800009
A11: 1164 | B11: LUIZ PEDRO DOS SANTOS | C11: 131 | D11: =A11-E11 -> 0 | E11: 1164 | F11: ID1140427100000002026040616104700007
A12: 1221 | B12: CIRO OLICE SALINE VILALBA | C12: 798 | D12: =A12-E12 -> 0 | E12: 1221 | F12: ID1140427100000002026040616105400004
... A137: 2899 | B137: JOSE RENATO DE FIGUEIREDO FILHO | C137: 810 | D137: =A137-E137 -> 0 | E137: 2899 | F137: ID1140427100000002026040616105400016
D138: =A138-E138 -> 0
D139: =A139-E139 -> 0
D140: =A140-E140 -> 0
D141: =A141-E141 -> 0
D142: =A142-E142 -> 0
D143: =A143-E143 -> 0
D144: =A144-E144 -> 0
D145: =A145-E145 -> 0
D146: =A146-E146 -> 0
