Workbook

Sheet BASES
A1: CONCRETA | E1: FGTS
M2: INSS | Q2: VALOR SALARIO FAMILIA | T2: RAT AJUSTADO 3x FAP | V2: VALOR GUIA LANÇAMENTO INSS
E3: BASE FGTS GERAL | F3: =E18+F18+G18+H18+I18 -> 957147.43 | G3: =F3-J5 -> 0 | I3: BASE FGTS SINTETICO | J3: 916114.64 | M3: BASE INSS | O3: BASE GERAL FOLHA | R3: 20% PATRONAL | S3: 5,8% TERCEIROS | U3: FAP | W3: IRRF FOLHA
I4: BASE FGTS 13 SINTETICO | J4: 41032.79 | M4: PROLABORE | N4: =V137 -> 8475.55 | O4: =O6 -> 926484.67 | P4: =eSocial!B3 -> 936260.22 | Q4: 0 | S4: =eSocial!D18 -> 53735.95 | T4: 3 | U4: =IF(A1="CONCRETA",1.2393,1.0312) -> 1.2393 | V4: =U6+R8+S5+O13-Q4 -> 363764.74 | W4: =X18+Y18+Z18 -> 30463.96 | X4: =DCTFWeb!G19 -> 30463.96
F5: BASE | G5: VALOR | J5: =SUM(J3:J4) -> 957147.43 | M5: AUTONOMOS | N5: =Q18 -> 1300 | O5: BASE TOTAL FOLHA | P5: =O4-P4+N6 -> -1.6370905e-10 | S5: =O6*0.058 -> 53736.111 | U5: =T4*U4 -> 3.7179
E6: CLT 8% | F6: =(E18+F18+G18+H18+I18)-F7 -> 953406.99 | G6: =F6*0.08 -> 76272.559 | N6: =SUM(N4:N5) -> 9775.55 | O6: =M8+N8+N9-N4 -> 926484.67 | R6: =N6*0.2 -> 1955.11 | S6: =eSocial!B17 -> 1955.11 | U6: =O6*(U5/100) -> 34445.774 | V6: =eSocial!B23 -> 34445.74 | W6: VALOR GUIA eCAC | X6: =DCTFWeb!G4 -> 394228.49
E7: APRENDIZES 2% | F7: =E51+E78+E144+E145+E178+E215+E227 -> 3740.44 | G7: =F7*0.02 -> 74.8088 | R7: =O6*0.2 -> 185296.93 | S7: =eSocial!B16 -> 185296.92
M8: =O18 -> 893927.43 | N8: =P18 -> 41032.79 | R8: =SUM(R6:R7) -> 187252.04 | X8: =X6-X4 -> 363764.53
E9: GRRF RECOLHIDAS 8% | F9: =G9/8*100 -> 82106.5 | G9: =GRRF!K15 -> 6568.52 | N9: =I18 -> 0 | O9: =U18 -> 0 | V9: =V4-X8 -> 0.20840593
E10: GRRF RECOLHIDAS 2% | F10: =G10/2*100 -> 0 | G10: 0 | N10: INSS | O10: =R18 -> 84246.86 | R10: DIF TERCEIROS | S10: =S4-S5 -> -0.16086
F11: =SUBTOTAL(9,F9:F10) -> 82106.5 | G11: =SUBTOTAL(9,G9:G10) -> 6568.52 | N11: INSS 13 | O11: =S18 -> 3500.33 | R11: DIF PATRONAL | S11: =S7-R7 -> -0.014
N12: INSS FERIAS | O12: =T18 -> 583.62 | R12: DIF RAT | S12: =V6-U6 -> -0.03354593
E13: FGTS DIGITAL 8% | F13: =F6-F9 -> 871300.49 | G13: =F13*0.08 -> 69704.039 | N13: SEGURADOS | O13: =SUM(O9:O12) -> 88330.81 | P13: =eSocial!D14 -> 88330.81 | Q13: =P13-O13 -> 0
E14: FGTS DIGITAL 2% | F14: =F7-F10 -> 3740.44 | G14: =F14*0.02 -> 74.8088 | H14: FGTS DIGITAL
G15: =SUM(G13:G14) -> 69778.848 | H15: 69777.46 | I15: =G15-H15 -> 1.388 | J15: =H15-J199 -> 69597.31
E18: =E279 -> 885451.88 | F18: =F279 -> 30662.76 | G18: =G279 -> 2423.95 | H18: =H279 -> 38608.84 | I18: =I279 -> 0 | J18: =J279 -> 70611.7 | K18: =K279 -> 2453.03 | L18: =L279 -> 193.92 | ... AD18: =AD279 -> 364294.91
A19: NOME | B19: CCUSTO | C19: CODSITUACAO | D19: CODTIPO | E19: BASEFGTS | F19: BASEFGTSAVPREVIO | G19: BASEFGTS13AVPREVIO | H19: BASEFGTS13 | I19: BASEFGTSDIFSAL | J19: FGTS_MES | K19: FGTS_AVISO | L19: FGTS13_AVISO | M19: FGTS13 | N19: FGTSDIF | O19: BASEINSS | P19: BASEINSS13 | Q19: BASE_INSS_AUTONOMO | R19: INSS | S19: INSS13 | T19: INSSFERIAS | U19: INSSDIFSAL | V19: BASEIRRF | W19: BASEIRRFFERIAS | X19: IRRF | Y19: IRRF13 | Z19: IRRFFERIAS | AA19: INSS RAT AJUSTADO | AB19: INSS EMPRESA | AC19: INSS TERCEIROS | AD19: TOTAL GUIA | AE19: COMPARA BASE FGTS | AF19: COMPARA VALOR FGTS | AG19: Nome Trabalhador | AH19: Base Remuneracao Total | AI19: Valor FGTS na Guia | AJ19: COMPARA BASES INSS | AK19: COMPARA VALOR INSS | AL19: Nome | AM19: Governo - Base INSS | AN19: Governo - Valor INSS | AO19: Governo - Base INSS - 13° Salário | AP19: Governo - Valor INSS - 13° Salário
A20: ABNER DAVID MIRANDA CARDOSO | B20: CDHU - Ilha Solteira "D" 100 U.H. | C20: A | D20: N | E20: 2354.01 | F20: 0 | G20: 0 | H20: 0 | I20: 0 | J20: 188.32 | K20: 0 | L20: 0 | M20: 0 | N20: 0 | O20: 2354.01 | P20: 0 | Q20: 0 | R20: 187.54 | S20: 0 | T20: 0 | U20: 0 | V20: 2354.01 | W20: 0 | X20: 0 | Y20: 0 | Z20: 0 | AA20: 87.52 | AB20: 470.8 | AC20: 136.53 | AD20: 882.39 | AE20: =(E20+F20+G20+H20+I20)-AH20 -> 0 | AF20: =(J20+K20+L20+M20+N20)-AI20 -> 0 | AG20: ABNER DAVID MIRANDA CARDOSO | AH20: 2354.01 | AI20: 188.32 | AJ20: =(O20+P20)-(AM20+AO20) -> 0 | AK20: =(R20+S20+T20+U20)-(AN20+AP20) -> 0 | AL20: ABNER DAVID MIRANDA CARDOSO | AM20: 2354.01 | AN20: 187.54 | AO20: 0 | AP20: 0
A21: ADEMAR DE JESUS | B21: Coleta de Lixo Varzea Grande MT | C21: A | D21: N | E21: 3702.68 | F21: 0 | G21: 0 | H21: 0 | I21: 0 | J21: 296.21 | K21: 0 | L21: 0 | M21: 0 | N21: 0 | O21: 3702.68 | P21: 0 | Q21: 0 | R21: 332.91 | S21: 0 | T21: 0 | U21: 0 | V21: 3702.68 | W21: 0 | X21: 0 | Y21: 0 | Z21: 0 | AA21: 137.66 | AB21: 740.54 | AC21: 214.76 | AD21: 1425.86 | AE21: =(E21+F21+G21+H21+I21)-AH21 -> 0 | AF21: =(J21+K21+L21+M21+N21)-AI21 -> 0 | AG21: ADEMAR DE JESUS | AH21: 3702.68 | AI21: 296.21 | AJ21: =(O21+P21)-(AM21+AO21) -> 0 | AK21: =(R21+S21+T21+U21)-(AN21+AP21) -> 0 | AL21: ADEMAR DE JESUS | AM21: 3702.68 | AN21: 332.91 | AO21: 0 | AP21: 0
A22: ADILSON GABRIEL DIAS FERREIRA MIRANDA | B22: Coleta de Lixo Varzea Grande MT | C22: A | D22: N | E22: 3716.01 | F22: 0 | G22: 0 | H22: 0 | I22: 0 | J22: 297.28 | K22: 0 | L22: 0 | M22: 0 | N22: 0 | O22: 3716.01 | P22: 0 | Q22: 0 | R22: 334.51 | S22: 0 | T22: 0 | U22: 0 | V22: 3716.01 | W22: 0 | X22: 0 | Y22: 0 | Z22: 0 | AA22: 138.16 | AB22: 743.2 | AC22: 215.53 | AD22: 1431.4 | AE22: =(E22+F22+G22+H22+I22)-AH22 -> 0 | AF22: =(J22+K22+L22+M22+N22)-AI22 -> 0 | AG22: ADILSON GABRIEL DIAS FERREIRA MIRANDA | AH22: 3716.01 | AI22: 297.28 | AJ22: =(O22+P22)-(AM22+AO22) -> 0 | AK22: =(R22+S22+T22+U22)-(AN22+AP22) -> 0 | AL22: ADILSON GABRIEL DIAS FERREIRA MIRANDA | AM22: 3716.01 | AN22: 334.51 | AO22: 0 | AP22: 0
A23: ADRIANO FERREIRA | B23: CDHU - Piratininga "E1" 56 U.H. | C23: A | D23: N | E23: 1839.59 | F23: 0 | G23: 0 | H23: 0 | I23: 0 | J23: 147.17 | K23: 0 | L23: 0 | M23: 0 | N23: 0 | O23: 1839.59 | P23: 0 | Q23: 0 | R23: 141.24 | S23: 0 | T23: 0 | U23: 0 | V23: 1839.59 | W23: 0 | X23: 0 | Y23: 0 | Z23: 0 | AA23: 68.39 | AB23: 367.92 | AC23: 106.7 | AD23: 684.25 | AE23: =(E23+F23+G23+H23+I23)-AH23 -> 0 | AF23: =(J23+K23+L23+M23+N23)-AI23 -> 0.01 | AG23: ADRIANO FERREIRA | AH23: 1839.59 | AI23: 147.16 | AJ23: =(O23+P23)-(AM23+AO23) -> 0 | AK23: =(R23+S23+T23+U23)-(AN23+AP23) -> 0 | AL23: ADRIANO FERREIRA | AM23: 1839.59 | AN23: 141.24 | AO23: 0 | AP23: 0
A24: AGNALDO GUIMARAES | B24: Coleta de Lixo Varzea Grande MT | C24: A | D24: N | E24: 3869.42 | F24: 0 | G24: 0 | H24: 0 | I24: 0 | J24: 309.55 | K24: 0 | L24: 0 | M24: 0 | N24: 0 | O24: 3869.42 | P24: 0 | Q24: 0 | R24: 352.91 | S24: 0 | T24: 0 | U24: 0 | V24: 3869.42 | W24: 0 | X24: 0 | Y24: 0 | Z24: 0 | AA24: 143.86 | AB24: 773.88 | AC24: 224.43 | AD24: 1495.08 | AE24: =(E24+F24+G24+H24+I24)-AH24 -> 0 | AF24: =(J24+K24+L24+M24+N24)-AI24 -> 0 | AG24: AGNALDO GUIMARAES | AH24: 3869.42 | AI24: 309.55 | AJ24: =(O24+P24)-(AM24+AO24) -> 0 | AK24: =(R24+S24+T24+U24)-(AN24+AP24) -> 0 | AL24: AGNALDO GUIMARAES | AM24: 3869.42 | AN24: 352.91 | AO24: 0 | AP24: 0
A25: AGNALDO NORBERTO DA SILVA | B25: Coleta de Lixo Varzea Grande MT | C25: A | D25: N | E25: 6768.67 | F25: 0 | G25: 0 | H25: 0 | I25: 0 | J25: 541.49 | K25: 0 | L25: 0 | M25: 0 | N25: 0 | O25: 6768.67 | P25: 0 | Q25: 0 | R25: 749.11 | S25: 0 | T25: 0 | U25: 0 | V25: 6768.67 | W25: 0 | X25: 669.24 | Y25: 0 | Z25: 0 | AA25: 251.65 | AB25: 1353.73 | AC25: 392.58 | AD25: 2747.08 | AE25: =(E25+F25+G25+H25+I25)-AH25 -> 0 | AF25: =(J25+K25+L25+M25+N25)-AI25 -> 0 | AG25: AGNALDO NORBETO DA SILVA | AH25: 6768.67 | AI25: 541.49 | AJ25: =(O25+P25)-(AM25+AO25) -> 0 | AK25: =(R25+S25+T25+U25)-(AN25+AP25) -> 0 | AL25: AGNALDO NORBETO DA SILVA | AM25: 6768.67 | AN25: 749.11 | AO25: 0 | AP25: 0
A26: AGRICOLA DIAS DA SILVA JUNIOR | B26: Coleta de Lixo Varzea Grande MT | C26: A | D26: N | E26: 5183.06 | F26: 0 | G26: 0 | H26: 0 | I26: 0 | J26: 414.64 | K26: 0 | L26: 0 | M26: 0 | N26: 0 | O26: 5183.06 | P26: 0 | Q26: 0 | R26: 527.13 | S26: 0 | T26: 0 | U26: 0 | V26: 5183.06 | W26: 0 | X26: 65.55 | Y26: 0 | Z26: 0 | AA26: 192.7 | AB26: 1036.61 | AC26: 300.62 | AD26: 2057.06 | AE26: =(E26+F26+G26+H26+I26)-AH26 -> 0 | AF26: =(J26+K26+L26+M26+N26)-AI26 -> 0 | AG26: AGRICOLA DIAS DA SILVA JUNIOR | AH26: 5183.06 | AI26: 414.64 | AJ26: =(O26+P26)-(AM26+AO26) -> 0 | AK26: =(R26+S26+T26+U26)-(AN26+AP26) -> 0 | AL26: AGRICOLA DIAS DA SILVA JUNIOR | AM26: 5183.06 | AN26: 527.13 | AO26: 0 | AP26: 0
A27: ALESSANDRO PASSOS BARROS | B27: Coleta de Lixo Varzea Grande MT | C27: A | D27: N | E27: 3984.86 | F27: 0 | G27: 0 | H27: 0 | I27: 0 | J27: 318.79 | K27: 0 | L27: 0 | M27: 0 | N27: 0 | O27: 3984.86 | P27: 0 | Q27: 0 | R27: 366.77 | S27: 0 | T27: 0 | U27: 0 | V27: 3984.86 | W27: 0 | X27: 0 | Y27: 0 | Z27: 0 | AA27: 148.15 | AB27: 796.97 | AC27: 231.12 | AD27: 1543.02 | AE27: =(E27+F27+G27+H27+I27)-AH27 -> 0 | AF27: =(J27+K27+L27+M27+N27)-AI27 -> 0.01 | AG27: ALESSANDRO PASSOS BARROS | AH27: 3984.86 | AI27: 318.78 | AJ27: =(O27+P27)-(AM27+AO27) -> 0 | AK27: =(R27+S27+T27+U27)-(AN27+AP27) -> 0 | AL27: ALESSANDRO PASSOS BARROS | AM27: 3984.86 | AN27: 366.77 | AO27: 0 | AP27: 0
A28: ALEX MATHEUS TAVARES CORREA | B28: Coleta de Lixo Varzea Grande MT | C28: A | D28: N | E28: 3045.47 | F28: 0 | G28: 0 | H28: 0 | I28: 0 | J28: 243.64 | K28: 0 | L28: 0 | M28: 0 | N28: 0 | O28: 3045.47 | P28: 0 | Q28: 0 | R28: 254.04 | S28: 0 | T28: 0 | U28: 0 | V28: 3045.47 | W28: 0 | X28: 0 | Y28: 0 | Z28: 0 | AA28: 113.23 | AB28: 609.09 | AC28: 176.64 | AD28: 1153 | AE28: =(E28+F28+G28+H28+I28)-AH28 -> 0 | AF28: =(J28+K28+L28+M28+N28)-AI28 -> 0.01 | AG28: ALEX MATHEUS TAVARES CORREA | AH28: 3045.47 | AI28: 243.63 | AJ28: =(O28+P28)-(AM28+AO28) -> 0 | AK28: =(R28+S28+T28+U28)-(AN28+AP28) -> 0 | AL28: ALEX MATHEUS TAVARES CORREA | AM28: 3045.47 | AN28: 254.04 | AO28: 0 | AP28: 0
A29: ALEXANDRE FERNANDO RAMOS VIANA | B29: Embasa Lote 02 - Municipio de Guanambi BA | C29: A | D29: A | E29: 0 | F29: 0 | G29: 0 | H29: 0 | I29: 0 | J29: 0 | K29: 0 | L29: 0 | M29: 0 | N29: 0 | O29: 0 | P29: 0 | Q29: 1300 | R29: 0 | S29: 0 | T29: 0 | U29: 0 | V29: 1300 | W29: 0 | X29: 0 | Y29: 0 | Z29: 0 | AA29: 0 | AB29: 0 | AC29: 0 | AD29: 0 | AE29: =(E29+F29+G29+H29+I29)-AH29 -> 0 | AF29: =(J29+K29+L29+M29+N29)-AI29 -> 0 | AJ29: =(O29+P29)-(AM29+AO29) -> 0 | AK29: =(R29+S29+T29+U29)-(AN29+AP29) -> 0
A30: ALLAN PETERSON RODRIGUES DE FREITAS | B30: Coleta de Lixo Varzea Grande MT | C30: A | D30: N | E30: 6876.33 | F30: 0 | G30: 0 | H30: 0 | I30: 0 | J30: 550.11 | K30: 0 | L30: 0 | M30: 0 | N30: 0 | O30: 6876.33 | P30: 0 | Q30: 0 | R30: 764.18 | S30: 0 | T30: 0 | U30: 0 | V30: 6876.33 | W30: 0 | X30: 709.04 | Y30: 0 | Z30: 0 | AA30: 255.66 | AB30: 1375.27 | AC30: 398.83 | AD30: 2793.93 | AE30: =(E30+F30+G30+H30+I30)-AH30 -> 0 | AF30: =(J30+K30+L30+M30+N30)-AI30 -> 0.01 | AG30: ALLAN PETERSON RODRIGUES DE FREITAS | AH30: 6876.33 | AI30: 550.1 | AJ30: =(O30+P30)-(AM30+AO30) -> 0 | AK30: =(R30+S30+T30+U30)-(AN30+AP30) -> 0 | AL30: ALLAN PETERSON RODRIGUES DE FREITAS | AM30: 6876.33 | AN30: 764.18 | AO30: 0 | AP30: 0
A31: ALTEVI JUARI PEREIRA | B31: Coleta de Lixo Varzea Grande MT | C31: A | D31: N | E31: 5730.19 | F31: 0 | G31: 0 | H31: 0 | I31: 0 | J31: 458.42 | K31: 0 | L31: 0 | M31: 0 | N31: 0 | O31: 5730.19 | P31: 0 | Q31: 0 | R31: 603.72 | S31: 0 | T31: 0 | U31: 0 | V31: 5730.19 | W31: 0 | X31: 284.41 | Y31: 0 | Z31: 0 | AA31: 213.04 | AB31: 1146.04 | AC31: 332.35 | AD31: 2295.15 | AE31: =(E31+F31+G31+H31+I31)-AH31 -> 0 | AF31: =(J31+K31+L31+M31+N31)-AI31 -> 0.01 | AG31: ALTEVI JUARI PEREIRA | AH31: 5730.19 | AI31: 458.41 | AJ31: =(O31+P31)-(AM31+AO31) -> 0 | AK31: =(R31+S31+T31+U31)-(AN31+AP31) -> 0 | AL31: ALTEVI JUARI PEREIRA | AM31: 5730.19 | AN31: 603.72 | AO31: 0 | AP31: 0
A32: ALVARO RUPPENTHAL | B32: Coleta de Lixo Varzea Grande MT | C32: D | D32: N | E32: 576.08 | F32: 0 | G32: 0 | H32: 1801.08 | I32: 0 | J32: 46.09 | K32: 0 | L32: 0 | M32: 144.09 | N32: 0 | O32: 576.08 | P32: 1801.08 | Q32: 0 | R32: 43.2 | S32: 137.77 | T32: 0 | U32: 0 | V32: 576.08 | W32: 0 | X32: 0 | Y32: 0 | Z32: 0 | AA32: 88.38 | AB32: 475.43 | AC32: 137.88 | AD32: 882.66 | AE32: =(E32+F32+G32+H32+I32)-AH32 -> 2377.16 | AF32: =(J32+K32+L32+M32+N32)-AI32 -> 190.18 | AJ32: =(O32+P32)-(AM32+AO32) -> 0 | AK32: =(R32+S32+T32+U32)-(AN32+AP32) -> 0 | AL32: ALVARO RUPPENTHAL | AM32: 576.08 | AN32: 43.2 | AO32: 1801.08 | AP32: 137.77
A33: ALYSON CAVALCANTE DO CARMO | B33: CDHU - Balbinos "D" 19 U.H. | C33: A | D33: N | E33: 784.67 | F33: 0 | G33: 0 | H33: 0 | I33: 0 | J33: 62.77 | K33: 0 | L33: 0 | M33: 0 | N33: 0 | O33: 784.67 | P33: 0 | Q33: 0 | R33: 58.85 | S33: 0 | T33: 0 | U33: 0 | V33: 784.67 | W33: 0 | X33: 0 | Y33: 0 | Z33: 0 | AA33: 29.17 | AB33: 156.93 | AC33: 45.51 | AD33: 290.47 | AE33: =(E33+F33+G33+H33+I33)-AH33 -> 0 | AF33: =(J33+K33+L33+M33+N33)-AI33 -> 0 | AG33: ALYSON CAVALCANTE DO CARMO | AH33: 784.67 | AI33: 62.77 | AJ33: =(O33+P33)-(AM33+AO33) -> 0 | AK33: =(R33+S33+T33+U33)-(AN33+AP33) -> 0 | AL33: ALYSON CAVALCANTE DO CARMO | AM33: 784.67 | AN33: 58.85 | AO33: 0 | AP33: 0
A34: ANA LAURA SILVA SOARES | B34: CDHU - Ilha Solteira "D" 100 U.H. | C34: A | D34: N | E34: 2839.05 | F34: 0 | G34: 0 | H34: 0 | I34: 0 | J34: 227.12 | K34: 0 | L34: 0 | M34: 0 | N34: 0 | O34: 2839.05 | P34: 0 | Q34: 0 | R34: 231.19 | S34: 0 | T34: 0 | U34: 0 | V34: 2839.05 | W34: 0 | X34: 0 | Y34: 0 | Z34: 0 | AA34: 105.55 | AB34: 567.81 | AC34: 164.66 | AD34: 1069.22 | AE34: =(E34+F34+G34+H34+I34)-AH34 -> 0 | AF34: =(J34+K34+L34+M34+N34)-AI34 -> 0 | AG34: ANA LAURA SILVA SOARES | AH34: 2839.05 | AI34: 227.12 | AJ34: =(O34+P34)-(AM34+AO34) -> 0 | AK34: =(R34+S34+T34+U34)-(AN34+AP34) -> 0 | AL34: ANA LAURA SILVA SOARES | AM34: 2839.05 | AN34: 231.19 | AO34: 0 | AP34: 0
A35: ANDERSON DA CONCEIÇÃO SANTOS | B35: CDHU - Duartina "E1" "E2" 128 U.H. | C35: A | D35: N | E35: 2945.87 | F35: 0 | G35: 0 | H35: 0 | I35: 0 | J35: 235.67 | K35: 0 | L35: 0 | M35: 0 | N35: 0 | O35: 2945.87 | P35: 0 | Q35: 0 | R35: 242.09 | S35: 0 | T35: 0 | U35: 0 | V35: 2945.87 | W35: 0 | X35: 0 | Y35: 0 | Z35: 0 | AA35: 109.52 | AB35: 589.17 | AC35: 170.86 | AD35: 1111.65 | AE35: =(E35+F35+G35+H35+I35)-AH35 -> 0 | AF35: =(J35+K35+L35+M35+N35)-AI35 -> 0.01 | AG35: ANDERSON DA CONCEICAO SANTOS | AH35: 2945.87 | AI35: 235.66 | AJ35: =(O35+P35)-(AM35+AO35) -> 0 | AK35: =(R35+S35+T35+U35)-(AN35+AP35) -> 0 | AL35: ANDERSON DA CONCEICAO SANTOS | AM35: 2945.87 | AN35: 242.09 | AO35: 0 | AP35: 0
A36: ANDERSON JOSE CONOTO LANDER | B36: Coleta de Lixo Varzea Grande MT | C36: A | D36: N | E36: 3571.75 | F36: 0 | G36: 0 | H36: 0 | I36: 0 | J36: 285.74 | K36: 0 | L36: 0 | M36: 0 | N36: 0 | O36: 3571.75 | P36: 0 | Q36: 0 | R36: 317.19 | S36: 0 | T36: 0 | U36: 0 | V36: 3571.75 | W36: 0 | X36: 0 | Y36: 0 | Z36: 0 | AA36: 132.79 | AB36: 714.35 | AC36: 207.16 | AD36: 1371.5 | AE36: =(E36+F36+G36+H36+I36)-AH36 -> 0 | AF36: =(J36+K36+L36+M36+N36)-AI36 -> 0 | AG36: ANDERSON JOSE CONOTO LANDER | AH36: 3571.75 | AI36: 285.74 | AJ36: =(O36+P36)-(AM36+AO36) -> 0 | AK36: =(R36+S36+T36+U36)-(AN36+AP36) -> 0 | AL36: ANDERSON JOSE CONOTO LANDER | AM36: 3571.75 | AN36: 317.19 | AO36: 0 | AP36: 0
A37: ANDERSON NEVES FERREIRA | B37: Coleta de Lixo Varzea Grande MT | C37: A | D37: N | E37: 6411.17 | F37: 0 | G37: 0 | H37: 0 | I37: 0 | J37: 512.89 | K37: 0 | L37: 0 | M37: 0 | N37: 0 | O37: 6411.17 | P37: 0 | Q37: 0 | R37: 699.06 | S37: 0 | T37: 0 | U37: 0 | V37: 6411.17 | W37: 0 | X37: 537.09 | Y37: 0 | Z37: 0 | AA37: 238.36 | AB37: 1282.23 | AC37: 371.85 | AD37: 2591.5 | AE37: =(E37+F37+G37+H37+I37)-AH37 -> 0 | AF37: =(J37+K37+L37+M37+N37)-AI37 -> 0 | AG37: ANDERSON NEVES FERREIRA | AH37: 6411.17 | AI37: 512.89 | AJ37: =(O37+P37)-(AM37+AO37) -> 0 | AK37: =(R37+S37+T37+U37)-(AN37+AP37) -> 0 | AL37: ANDERSON NEVES FERREIRA | AM37: 6411.17 | AN37: 699.06 | AO37: 0 | AP37: 0
A38: ANDRE HENRIQUE SANTOS DE PAULA | B38: Coleta de Lixo Varzea Grande MT | C38: A | D38: N | E38: 3437.75 | F38: 0 | G38: 0 | H38: 0 | I38: 0 | J38: 275.02 | K38: 0 | L38: 0 | M38: 0 | N38: 0 | O38: 3437.75 | P38: 0 | Q38: 0 | R38: 301.11 | S38: 0 | T38: 0 | U38: 0 | V38: 3437.75 | W38: 0 | X38: 0 | Y38: 0 | Z38: 0 | AA38: 127.81 | AB38: 687.55 | AC38: 199.39 | AD38: 1315.86 | AE38: =(E38+F38+G38+H38+I38)-AH38 -> 0 | AF38: =(J38+K38+L38+M38+N38)-AI38 -> 0 | AG38: ANDRE HENRIQUE SANTOS DE PAULA | AH38: 3437.75 | AI38: 275.02 | AJ38: =(O38+P38)-(AM38+AO38) -> 0 | AK38: =(R38+S38+T38+U38)-(AN38+AP38) -> 0 | AL38: ANDRE HENRIQUE SANTOS DE PAULA | AM38: 3437.75 | AN38: 301.11 | AO38: 0 | AP38: 0
A39: ANTONIO MARCOS DE PAULA LINO | B39: Oficina | C39: D | D39: N | E39: 5834.26 | F39: 5161.33 | G39: 367.38 | H39: 1836.9 | I39: 0 | J39: 466.74 | K39: 412.91 | L39: 29.39 | M39: 146.95 | N39: 0 | O39: 5834.26 | P39: 2204.28 | Q39: 0 | R39: 618.29 | S39: 174.06 | T39: 0 | U39: 0 | V39: 5834.26 | W39: 0 | X39: 323.84 | Y39: 0 | Z39: 0 | AA39: 298.86 | AB39: 1607.71 | AC39: 466.24 | AD39: 3165.16 | AE39: =(E39+F39+G39+H39+I39)-AH39 -> 13199.87 | AF39: =(J39+K39+L39+M39+N39)-AI39 -> 1055.99 | AJ39: =(O39+P39)-(AM39+AO39) -> 0 | AK39: =(R39+S39+T39+U39)-(AN39+AP39) -> 0 | AL39: ANTONIO MARCOS DE PAULA LINO | AM39: 5834.26 | AN39: 618.29 | AO39: 2204.28 | AP39: 174.06
A40: ANTONIO MARTINS DA SILVA | B40: Coleta de Lixo Varzea Grande MT | C40: A | D40: N | E40: 3781.66 | F40: 0 | G40: 0 | H40: 0 | I40: 0 | J40: 302.53 | K40: 0 | L40: 0 | M40: 0 | N40: 0 | O40: 3781.66 | P40: 0 | Q40: 0 | R40: 342.38 | S40: 0 | T40: 0 | U40: 0 | V40: 3781.66 | W40: 0 | X40: 0 | Y40: 0 | Z40: 0 | AA40: 140.6 | AB40: 756.33 | AC40: 219.34 | AD40: 1458.65 | AE40: =(E40+F40+G40+H40+I40)-AH40 -> 0 | AF40: =(J40+K40+L40+M40+N40)-AI40 -> 0 | AG40: ANTONIO MARTINS DA SILVA | AH40: 3781.66 | AI40: 302.53 | AJ40: =(O40+P40)-(AM40+AO40) -> 0 | AK40: =(R40+S40+T40+U40)-(AN40+AP40) -> 0 | AL40: ANTONIO MARTINS DA SILVA | AM40: 3781.66 | AN40: 342.38 | AO40: 0 | AP40: 0
A41: ANTONIO MENDES DA LUZ | B41: Coleta de Lixo Varzea Grande MT | C41: A | D41: N | E41: 3396.76 | F41: 0 | G41: 0 | H41: 0 | I41: 0 | J41: 271.74 | K41: 0 | L41: 0 | M41: 0 | N41: 0 | O41: 3396.76 | P41: 0 | Q41: 0 | R41: 296.2 | S41: 0 | T41: 0 | U41: 0 | V41: 3396.76 | W41: 0 | X41: 0 | Y41: 0 | Z41: 0 | AA41: 126.29 | AB41: 679.35 | AC41: 197.01 | AD41: 1298.85 | AE41: =(E41+F41+G41+H41+I41)-AH41 -> 0 | AF41: =(J41+K41+L41+M41+N41)-AI41 -> 0 | AG41: ANTONIO MENDES DA LUZ | AH41: 3396.76 | AI41: 271.74 | AJ41: =(O41+P41)-(AM41+AO41) -> 0 | AK41: =(R41+S41+T41+U41)-(AN41+AP41) -> 0 | AL41: ANTONIO MENDES DA LUZ | AM41: 3396.76 | AN41: 296.2 | AO41: 0 | AP41: 0
A42: ANTONIO ROBERTO DE SOUZA | B42: CDHU - Bocaina "H1" "H2" 96 U.H. | C42: A | D42: N | E42: 3169.1 | F42: 0 | G42: 0 | H42: 0 | I42: 0 | J42: 253.53 | K42: 0 | L42: 0 | M42: 0 | N42: 0 | O42: 3169.1 | P42: 0 | Q42: 0 | R42: 268.88 | S42: 0 | T42: 0 | U42: 0 | V42: 3169.1 | W42: 0 | X42: 0 | Y42: 0 | Z42: 0 | AA42: 117.82 | AB42: 633.82 | AC42: 183.81 | AD42: 1204.33 | AE42: =(E42+F42+G42+H42+I42)-AH42 -> 0 | AF42: =(J42+K42+L42+M42+N42)-AI42 -> 0.01 | AG42: ANTONIO ROBERTO DE SOUZA | AH42: 3169.1 | AI42: 253.52 | AJ42: =(O42+P42)-(AM42+AO42) -> 0 | AK42: =(R42+S42+T42+U42)-(AN42+AP42) -> 0 | AL42: ANTONIO ROBERTO DE SOUZA | AM42: 3169.1 | AN42: 268.88 | AO42: 0 | AP42: 0
...

Sheet RATEIOS
A3: Rótulos de Linha | B3: Soma de Valor FGTS na Guia | C3: Soma de IRRF | E3: Soma de Valor FGTS na Guia | F3: Soma de IRRF
A4: BR-060/GO - Goiania GO | C4: 0 | E4: 0 | F4: 0
A5: BR-488 e 459 - Lorena/Piquete/Aparecida | B5: 1988.74 | C5: 217.22 | E5: 1988.74 | F5: 217.22
A6: CDHU - Balbinos "D" 19 U.H. | B6: 802.57 | C6: 0 | E6: 802.57 | F6: 0
A7: CDHU - Birigui "D" 143 U.H. | B7: 2594.84 | C7: 1752.3 | E7: 2594.84 | F7: 1752.3
A8: CDHU - Bocaina "H1" "H2" 96 U.H. | B8: 1812.89 | C8: 0 | E8: 1812.89 | F8: 0
A9: CDHU - Duartina "E1" "E2" 128 U.H. | B9: 3437.65 | C9: 1453.82 | E9: 3437.65 | F9: 1453.82
A10: CDHU - Ilha Solteira "D" 100 U.H. | B10: 1817.25 | C10: 0 | E10: 1817.25 | F10: 0
A11: CDHU - Mirandopolis "D" 259 U.H. | B11: 234.32 | C11: 0 | E11: 234.32 | F11: 0
A12: CDHU - Piratininga "E1" 56 U.H. | B12: 1674.4 | C12: 674.97 | E12: 1674.4 | F12: 674.97
A13: CDHU - Sabino "E1" "E2" 190 U.H. | B13: 2402.25 | C13: 92.21 | E13: 2402.25 | F13: 92.21
A14: Coleta de Lixo Varzea Grande MT | B14: 44578.71 | C14: 21405.27 | E14: 44578.71 | F14: 21405.27
A15: DER - Ipaussu | C15: 0 | E15: 0 | F15: 0
A16: Embasa Lote 02 - Municipio de Guanambi BA | C16: 0 | E16: 0 | F16: 0
A17: Embasa Lote 02 - Municipio de Paramirim BA | B17: 2515.51 | C17: 634.65 | E17: 2515.51 | F17: 634.65
A18: Financeiro | B18: 2791.84 | C18: 2711.65 | E18: 2791.84 | F18: 2711.65
A19: Oficina | B19: 3126.49 | C19: 1422.52 | E19: 3126.49 | F19: 1422.52
A20: Total Geral | B20: 69777.46 | C20: 30364.61

Sheet eSocial
A1: Resumo da Folha de Pagamento
A2: Bases de Cálculo | B2: Valor
A3: 11 - Base de cálculo da contribuição previdenciária | B3: 936260.22
A4: Contribuições do Segurado | B4: Valor Descontado | C4: Valor Calculado
A5: Valor total da contribuição | B5: 88330.81 | C5: 88330.81 | D5: =C5-B5 -> 0
A6: Estabelecimento 04.327.690/0001-49
A7: Estabelecimento 00.900.255/9107-74
A8: Estabelecimento 00.900.255/9018-79
A9: Estabelecimento 00.900.255/9076-75
A10: Estabelecimento 00.900.296/3171-79
A11: Estabelecimento 00.900.255/9056-72
A12: Informações consolidadas das contribuições sociais
A13: Codigo Receita | B13: Valor | C13: Valor Suspenso
A14: 1082-01 - CP SEGURADOS - EMPREGADOS/AVULSOS | B14: 87398.5 | C14: - | D14: =B14+B15 -> 88330.81
A15: 1099-01 - CP SEGURADOS - CONTRIBUINTES INDIVIDUAIS - 11% | B15: 932.31 | C15: -
A16: 1138-01 - CP PATRONAL - EMPREGADOS/AVULSOS | B16: 185296.92 | C16: -
A17: 1138-04 - CP PATRONAL - CONTRIBUINTES INDIVIDUAIS | B17: 1955.11 | C17: -
A18: 1170-01 - CP TERCEIROS - SALÁRIO EDUCAÇÃO | B18: 23162.08 | C18: - | D18: =B18+B19+B20+B21+B22 -> 53735.95
A19: 1176-01 - CP TERCEIROS - INCRA | B19: 1852.94 | C19: -
A20: 1181-01 - CP TERCEIROS - SENAI | B20: 9264.81 | C20: -
A21: 1184-01 - CP TERCEIROS - SESI | B21: 13897.25 | C21: -
A22: 1200-01 - CP TERCEIROS - SEBRAE | B22: 5558.87 | C22: -
A23: 1646-01 - CP PATRONAL - GILRAT AJUSTADO | B23: 34445.74 | C23: -

Sheet DCTFWeb
A1: DÉBITOS APURADOS | E1: SALDO A PAGAR
B2: Tributos/Códigos de Receita | D2: PA Débito | F2: Débito Apurado
A3: #VALUE!
A4: #VALUE! | B4: Total Apurado Empresa 04.327.690/0001-49 | E4: 394228.49 | G4: 394228.49
B5: #VALUE! | C5: Total CONTRIBUIÇÃO PREVIDENCIÁRIA SEGURADOS | E5: 88330.81 | G5: 88330.81
C6: 1082-01 CP SEGURADOS - EMPREGADOS/AVULSO | D6: 46266 | E6: 87398.5 | G6: 87398.5
C7: 1099-01 CP SEGURADOS - CONTRIBUINTES INDIVIDUAIS - 11% | D7: 46266 | E7: 932.31 | G7: 932.31
B8: #VALUE! | C8: Total CONTRIBUIÇÃO PREVIDENCIÁRIA PATRONAL | E8: 139727.82 | G8: 139727.82
C9: 1138-01 CP PATRONAL - EMPREGADOS/AVULSOS | D9: 46266 | E9: 116176.15 | G9: 116176.15
C10: 1138-04 CP PATRONAL - CONTRIBUINTES INDIVIDUAIS | D10: 46266 | E10: 1955.11 | G10: 1955.11
C11: 1646-01 CP PATRONAL - GILRAT AJUSTADO | D11: 46266 | E11: 21596.56 | G11: 21596.56
B12: #VALUE! | C12: Total CONTRIBUIÇÃO PARA OUTRAS ENTIDADES E FUNDOS | E12: 33691.06 | G12: 33691.06
C13: 1170-01 CP TERCEIROS - SALÁRIO EDUCAÇÃO | D13: 46266 | E13: 14522.01 | G13: 14522.01
C14: 1176-01 CP TERCEIROS - INCRA | D14: 46266 | E14: 1161.76 | G14: 1161.76
C15: 1181-01 CP TERCEIROS - SENAI | D15: 46266 | E15: 5808.8 | G15: 5808.8
C16: 1184-01 CP TERCEIROS - SESI | D16: 46266 | E16: 8713.21 | G16: 8713.21
C17: 1200-01 CP TERCEIROS - SEBRAE | D17: 46266 | E17: 3485.28 | G17: 3485.28
B18: #VALUE! | C18: Total IRRF | E18: 30463.96 | G18: 30463.96
C19: 0561-07 IRRF - RD TRB ASSAL PAÍS/AUS NO EXT A SERV PAÍS | D19: 46266 | E19: 30463.96 | G19: 30463.96
B20: #VALUE! | C20: Total Apurado - CNO 90.025.59018/79 | E20: 16759.21 | G20: 16759.21
B21: #VALUE! | C21: Total Apurado - CNO 90.025.59056/72 | E21: 26385.26 | G21: 26385.26
B22: #VALUE! | C22: Total Apurado - CNO 90.025.59076/75 | E22: 6599.49 | G22: 6599.49
B23: #VALUE! | C23: Total Apurado - CNO 90.025.59107/74 | E23: 39981.23 | G23: 39981.23
B24: #VALUE! | C24: Total Apurado - CNO 90.029.63171/79 | E24: 12289.65 | G24: 12289.65

Sheet GRRF
A1: NOME | B1: CHAPA | C1: CODTIPO | D1: FGTS QUITACAO | E1: FGTS MES ANTERIOR | F1: FGTS AVISO PREVIO | G1: FGTS ARTIGO 22 | H1: FGTS 13 SALARIO INDENIZADO | I1: FGTS 13 Sal rescisao | J1: TOTAL | K1: JÁ RECOLHIDO
A2: ALVARO RUPPENTHAL | B2: 00001831 | C2: N | D2: 46.08 | E2: 268.36 | G2: 861.15 | I2: 144.08 | J2: 1319.67 | K2: =D2+F2+H2+I2 -> 190.16
A3: ANTONIO MARCOS DE PAULA LINO | B3: 00001459 | C3: N | D3: 466.74 | F3: 412.9 | G3: 5454.03 | H3: 29.39 | I3: 146.95 | J3: 6510.01 | K3: =D3+F3+H3+I3 -> 1055.98
A4: BENTO PEREIRA AMADO | B4: 00001644 | C4: N | D4: 191.69 | F4: 23.46 | G4: 1648.61 | I4: 177.14 | J4: 2040.9 | K4: =D4+F4+H4+I4 -> 392.29
A5: CLAUDIO MODESTO | B5: 00001586 | C5: N | D5: 38.96 | E5: 176.17 | F5: 37.68 | G5: 1999.14 | I5: 125.62 | J5: 2377.57 | K5: =D5+F5+H5+I5 -> 202.26
A6: DANIEL DA SILVA FERREIRA | B6: 00001758 | C6: N | D6: 213.32 | F6: 270.14 | G6: 1092.36 | H6: 23.09 | I6: 207.81 | J6: 1806.72 | K6: =D6+F6+H6+I6 -> 714.36
A7: DIEGO RODRIGO DA CUNHA PARDINHO | B7: 00001968 | C7: N | D7: 137.35 | I7: 34.46 | J7: 171.81 | K7: =D7+F7+H7+I7 -> 171.81
A8: ELIANA APARECIDA DOMINGUES EMILIO | B8: 00001695 | C8: N | D8: 6.68 | E8: 188.65 | F8: 202.67 | G8: 748.66 | H8: 16.83 | I8: 134.7 | J8: 1298.19 | K8: =D8+F8+H8+I8 -> 360.88
A9: JORGE LUIS IBARRA GOMEZ | B9: 00001794 | C9: N | D9: 225.28 | F9: 269.35 | G9: 1083.88 | H9: 23.11 | I9: 208.03 | J9: 1809.65 | K9: =D9+F9+H9+I9 -> 725.77
A10: JOSE DOS SANTOS | B10: 00001701 | C10: N | D10: 417.76 | F10: 344.1 | G10: 1639.9 | H10: 29.62 | I10: 266.57 | J10: 2697.95 | K10: =D10+F10+H10+I10 -> 1058.05
A11: JOSE SEBASTIAO DOS SANTOS | B11: 00001650 | C11: N | D11: 231.34 | F11: 330.11 | G11: 2012.11 | H11: 24.33 | I11: 218.97 | J11: 2816.86 | K11: =D11+F11+H11+I11 -> 804.75
A12: REGINALDO CARVALHO SANTOS | B12: 00001971 | C12: N | E12: 128.72 | G12: 56.51 | I12: 12.56 | J12: 197.79 | K12: =D12+F12+H12+I12 -> 12.56
A13: ROMUALDO ADRIANO MARTINEZ PERES | B13: 00001930 | C13: N | D13: 5.61 | E13: 245.99 | F13: 325.72 | G13: 546.61 | H13: 27.14 | I13: 81.43 | J13: 1232.5 | K13: =D13+F13+H13+I13 -> 439.9
A14: VITOR CARLOS TAVARES | B14: 00001859 | C14: N | D14: 39.83 | E14: 283.13 | F14: 236.84 | G14: 983.62 | H14: 20.38 | I14: 142.7 | J14: 1706.5 | K14: =D14+F14+H14+I14 -> 439.75
D15: =SUM(D2:D14) -> 2020.64 | E15: =SUM(E2:E14) -> 1291.02 | F15: =SUM(F2:F14) -> 2452.97 | G15: =SUM(G2:G14) -> 18126.58 | H15: =SUM(H2:H14) -> 193.89 | I15: =SUM(I2:I14) -> 1901.02 | J15: =SUM(J2:J14) -> 25986.12 | K15: =SUM(K2:K14) -> 6568.52

Sheet EMPRESTIMOS
A1: CODCOLIGADA | B1: NOME | C1: CODSITUACAO | D1: VALOR | F1: Rótulos de Linha | G1: Soma de Valor
A2: 1 | B2: ADILSON GABRIEL DIAS FERREIRA MIRANDA | C2: A | D2: 629.12 | E2: =D2-G2 -> 0 | F2: ADILSON GABRIEL DIAS FERREIRA MIRANDA | G2: 629.12 | I2: =G2-J2 -> 0 | J2: 629.12 | K2: Emprestimo Consignado - Competência: set/2026 Períodos: 5 - ADILSON GABRIEL DIAS FERREIRA MIRANDA- 11075354170- 104- 3090- 159032250
A3: 1 | B3: ADRIANO FERREIRA | C3: A | D3: 483 | E3: =D3-G3 -> 0 | F3: ADRIANO FERREIRA | G3: 483 | I3: =G3-J3 -> 0 | J3: 483 | K3: Emprestimo Consignado - Competência: set/2026 Períodos: 5 - ADRIANO FERREIRA- 38433029878- 104- 3090- 082193433
A4: 1 | B4: ALEX MATHEUS TAVARES CORREA | C4: A | D4: 120.57 | E4: =D4-G4 -> 0 | F4: ALEX MATHEUS TAVARES CORREA | G4: 120.57 | I4: =G4-J4 -> 0 | J4: 120.57 | K4: Emprestimo Consignado - Competência: set/2026 Períodos: 5 - ALEX MATHEUS TAVARES CORREA- 05985413144- 104- 3090- 159035942
A5: 1 | B5: ALLAN PETERSON RODRIGUES DE FREITAS | C5: A | D5: 1397.69 | E5: =D5-G5 -> 0 | F5: ALLAN PETERSON RODRIGUES DE FREITAS | G5: 1397.69 | I5: =G5-J5 -> 0 | J5: 1397.69 | K5: Emprestimo Consignado - Competência: set/2026 Períodos: 5 - ALLAN PETERSON RODRIGUES DE FREITAS- 06837574159- 104- 3090- 157265789
A6: 1 | B6: ALTEVI JUARI PEREIRA | C6: A | D6: 707.74 | E6: =D6-G6 -> 0 | F6: ALTEVI JUARI PEREIRA | G6: 707.74 | I6: =G6-J6 -> 0 | J6: 707.74 | K6: Emprestimo Consignado - Competência: set/2026 Períodos: 5 - ALTEVI JUARI PEREIRA- 89202171149- 104- 3090- 157266254
A7: 1 | B7: ANDERSON DA CONCEIÇÃO SANTOS | C7: A | D7: 536.57 | E7: =D7-G7 -> 0 | F7: ANDERSON DA CONCEICAO SANTOS | G7: 536.57 | I7: =G7-J7 -> 0 | J7: 536.57 | K7: Emprestimo Consignado - Competência: set/2026 Períodos: 5 - ANDERSON DA CONCEIÇÃO SANTOS- 11463603550- 104- 3090- 154086867
A8: 1 | B8: ANDERSON NEVES FERREIRA | C8: A | D8: 498.81 | E8: =D8-G8 -> 0 | F8: ANDERSON NEVES FERREIRA | G8: 498.81 | I8: =G8-J8 -> 0 | J8: 498.81 | K8: Emprestimo Consignado - Competência: set/2026 Períodos: 5 - ANDERSON NEVES FERREIRA- 98933833153- 104- 3090- 159029535
A9: 1 | B9: ANDRE HENRIQUE SANTOS DE PAULA | C9: A | D9: 533.41 | E9: =D9-G9 -> 0 | F9: ANDRE HENRIQUE SANTOS DE PAULA | G9: 533.41 | I9: =G9-J9 -> 0 | J9: 533.41 | K9: Emprestimo Consignado - Competência: set/2026 Períodos: 5 - ANDRE HENRIQUE SANTOS DE PAULA- 06694872100- 104- 3090- 142857170
A10: 1 | B10: ANTONIO MARTINS DA SILVA | C10: A | D10: 623.63 | E10: =D10-G10 -> 0 | F10: ANTONIO MARTINS DA SILVA | G10: 623.63 | I10: =G10-J10 -> 0 | J10: 623.63 | K10: Emprestimo Consignado - Competência: set/2026 Períodos: 5 - ANTONIO MARTINS DA SILVA- 06189796117- 104- 3090- 157265428
A11: 1 | B11: ARNALDO FERREIRA DE MELO | C11: D | D11: 53.09 | E11: =D11-G11 -> 0 | F11: ARNALDO FERREIRA DE MELO | G11: 53.09 | I11: =G11-J11 -> 0 | J11: 53.09 | K11: Emprestimo Consignado - Competência: set/2026 Períodos: 5 - ARNALDO FERREIRA DE MELO- 08678807407- 104- 3090- 157264855
A12: 1 | B12: CARLITO PAULA DOS SANTOS | C12: A | D12: 1024.87 | E12: =D12-G12 -> 0 | F12: CARLITO PAULA DOS SANTOS | G12: 1024.87 | I12: =G12-J12 -> 0 | J12: 1024.87 | K12: Emprestimo Consignado - Competência: set/2026 Períodos: 5 - CARLITO PAULA DOS SANTOS- 36271056806- 104- 3090- 178323257
A13: 1 | B13: CARLOS ANDRE OLIVEIRA DA SILVA | C13: A | D13: 574.63 | E13: =D13-G13 -> 0 | F13: CARLOS ANDRE OLIVEIRA DA SILVA | G13: 574.63 | I13: =G13-J13 -> 0 | J13: 574.63 | K13: Emprestimo Consignado - Competência: set/2026 Períodos: 5 - CARLOS ANDRE OLIVEIRA DA SILVA- 52477668811- 104- 3090- 159174616
... A18: 1 | B18: CLEIVISON APARECIDO DA SILVA | C18: A | D18: 387.11 | E18: =D18-G18 -> 0 | F18: CLEIVISON APARECIDO DA SILVA | G18: 387.11 | I18: =G18-J18 -> 0 | J18: 387.11 | K18: Emprestimo Consignado - Competência: set/2026 Períodos: 5 - CLEIVISON APARECIDO DA SILVA- 92633285287- 104- 3090- 157266564
A19: 1 | B19: DANIEL DA SILVA FERREIRA | C19: D | D19: 1438.76 | E19: =D19-G19 -> 1438.76 | I19: =G19-J19 -> -1438.76 | J19: 1438.76 | K19: Emprestimo Consignado - Competência: set/2026 Períodos: 5 - DANIEL DA SILVA FERREIRA- 61458088375- 104- 3090- 159036124
A20: 1 | B20: DANIEL DOS SANTOS SOUZA | C20: A | D20: 146.05 | E20: =D20-G20 -> 0 | F20: DANIEL DOS SANTOS SOUZA | G20: 146.05 | I20: =G20-J20 -> 0 | J20: 146.05 | K20: Emprestimo Consignado - Competência: set/2026 Períodos: 5 - DANIEL DOS SANTOS SOUZA- 04056719110- 104- 3090- 157265738
A21: 1 | B21: DEJAIR BORGES DE ALMEIDA | C21: A | D21: 410.26 | E21: =D21-G21 -> 0 | F21: DEJAIR BORGES DE ALMEIDA | G21: 410.26 | I21: =G21-J21 -> 0 | J21: 410.26 | K21: Emprestimo Consignado - Competência: set/2026 Períodos: 5 - DEJAIR BORGES DE ALMEIDA- 05526813185- 104- 3090- 159032137
A22: 1 | B22: DERIK HENRIQUE DOS SANTOS ANUNCIACAO | C22: A | D22: 691.34 | E22: =D22-G22 -> 0 | F22: DERIK HENRIQUE DOS SANTOS ANUNCIACAO | G22: 691.34 | I22: =G22-J22 -> 0 | J22: 691.34 | K22: Emprestimo Consignado - Competência: set/2026 Períodos: 5 - DERIK HENRIQUE DOS SANTOS ANUNCIACAO- 07132055127- 104- 3090- 157265347
A23: 1 | B23: DOUGLAS ORTIS DE OLIVEIRA | C23: A | D23: 428.35 | E23: =D23-G23 -> 0 | F23: DOUGLAS ORTIS DE OLIVEIRA | G23: 428.35 | I23: =G23-J23 -> 0 | J23: 428.35 | K23: Emprestimo Consignado - Competência: set/2026 Períodos: 5 - DOUGLAS ORTIS DE OLIVEIRA- 06591997180- 104- 3090- 159032218
A24: 1 | B24: EDMILTON PEREIRA DE ARRUDA | C24: A | D24: 537.99 | E24: =D24-G24 -> 0 | F24: EDMILTON PEREIRA DE ARRUDA | G24: 537.99 | I24: =G24-J24 -> 0 | J24: 537.99 | K24: Emprestimo Consignado - Competência: set/2026 Períodos: 5 - EDMILTON PEREIRA DE ARRUDA- 04634736128- 104- 3090- 157263840
A25: 1 | B25: EDUARDO HENRIQUE LOPES LOURENCO | C25: P | D25: 690.32 | E25: =D25-G25 -> 0 | F25: EDUARDO HENRIQUE LOPES LOURENCO | G25: 690.32 | I25: =G25-J25 -> 0 | J25: 690.32 | K25: Emprestimo Consignado - Competência: set/2026 Períodos: 5 - EDUARDO HENRIQUE LOPES LOURENCO- 71158215185- 104- 3090- 157265126
A26: 1 | B26: ELIANA APARECIDA DOMINGUES EMILIO | C26: D | D26: 2610.49 | E26: =D26-G26 -> 2610.49 | I26: =G26-J26 -> -2610.49 | J26: 2610.49 | K26: Emprestimo Consignado - Competência: set/2026 Períodos: 5 - ELIANA APARECIDA DOMINGUES EMILIO- 33713192880- 104- 3090- 188455210
A27: 1 | B27: FERNANDA MONISE DIAS QUEIROZ | C27: A | D27: 64.68 | E27: =D27-G27 -> 0 | F27: FERNANDA MONISE DIAS QUEIROZ | G27: 64.68 | I27: =G27-J27 -> 0 | J27: 64.68 | K27: Emprestimo Consignado - Competência: set/2026 Períodos: 5 - FERNANDA MONISE DIAS QUEIROZ- 16028364428- 104- 3090- 163709375
A28: 1 | B28: FERNANDO URBANO | C28: A | D28: 325.92 | E28: =D28-G28 -> 0 | F28: FERNANDO URBANO | G28: 325.92 | I28: =G28-J28 -> 0 | J28: 325.92 | K28: Emprestimo Consignado - Competência: set/2026 Períodos: 5 - FERNANDO URBANO- 10101689837- 104- 2785- 866587750
A29: 1 | B29: GUILHERME DOS SANTOS CAVALCANTE | C29: A | D29: 649.52 | E29: =D29-G29 -> 0 | F29: GUILHERME DOS SANTOS CAVALCANTE | G29: 649.52 | I29: =G29-J29 -> 0 | J29: 649.52 | K29: Emprestimo Consignado - Competência: set/2026 Períodos: 5 - GUILHERME DOS SANTOS CAVALCANTE- 08987248216- 104- 3090- 159035276
A30: 1 | B30: GUILHERME GABRIEL PARRA | C30: A | D30: 458.7 | E30: =D30-G30 -> 0 | F30: GUILHERME GABRIEL PARRA | G30: 458.7 | I30: =G30-J30 -> 0 | J30: 458.7 | K30: Emprestimo Consignado - Competência: set/2026 Períodos: 5 - GUILHERME GABRIEL PARRA- 46546999889- 104- 3090- 932525862
A31: 1 | B31: ISMAEL CESAR DE SOUZA ESPIRITO SANTO | C31: A | D31: 592.08 | E31: =D31-G31 -> 0 | F31: ISMAEL CESAR DE SOUZA ESPIRITO SANTO | G31: 592.08 | I31: =G31-J31 -> 0 | J31: 592.08 | K31: Emprestimo Consignado - Competência: set/2026 Períodos: 5 - ISMAEL CESAR DE SOUZA ESPIRITO SANTO- 70173394108- 104- 3090- 159029462
A32: 1 | B32: ISRAEL BORGES DA SILVA | C32: A | D32: 390.48 | E32: =D32-G32 -> 0 | F32: ISRAEL BORGES DA SILVA | G32: 390.48 | I32: =G32-J32 -> 0 | J32: 390.48 | K32: Emprestimo Consignado - Competência: set/2026 Períodos: 5 - ISRAEL BORGES DA SILVA- 60981225390- 104- 3090- 159029845
A33: 1 | B33: IVANILDO RODRIGUES DE SOUZA | C33: A | D33: 642.24 | E33: =D33-G33 -> 0 | F33: IVANILDO RODRIGUES DE SOUZA | G33: 642.24 | I33: =G33-J33 -> 0 | J33: 642.24 | K33: Emprestimo Consignado - Competência: set/2026 Períodos: 5 - IVANILDO RODRIGUES DE SOUZA- 90061268100- 104- 3090- 157263875
A34: 1 | B34: JAMES CARVALHO ALMEIDA | C34: A | D34: 641.66 | E34: =D34-G34 -> 0 | F34: JAMES CARVALHO ALMEIDA | G34: 641.66 | I34: =G34-J34 -> 0 | J34: 641.66 | K34: Emprestimo Consignado - Competência: set/2026 Períodos: 5 - JAMES CARVALHO ALMEIDA- 99036614368- 104- 3090- 142251825
A35: 1 | B35: JEFF ALCIUS | C35: A | D35: 462.39 | E35: =D35-G35 -> 0 | F35: JEFF ALCIUS | G35: 462.39 | I35: =G35-J35 -> 0 | J35: 462.39 | K35: Emprestimo Consignado - Competência: set/2026 Períodos: 5 - JEFF ALCIUS- 70469807210- 104- 3090- 158968236
A36: 1 | B36: JEREMIAS VIEIRA DE LIMA | C36: A | D36: 232 | E36: =D36-G36 -> 0 | F36: JEREMIAS VIEIRA DE LIMA | G36: 232 | I36: =G36-J36 -> 0 | J36: 232 | K36: Emprestimo Consignado - Competência: set/2026 Períodos: 5 - JEREMIAS VIEIRA DE LIMA- 10282135308- 104- 3090- 142807440
A37: 1 | B37: JOADIR MENDES DA SILVA | C37: A | D37: 1076.3 | E37: =D37-G37 -> 0 | F37: JOADIR MENDES DA SILVA | G37: 1076.3 | I37: =G37-J37 -> 0 | J37: 1076.3 | K37: Emprestimo Consignado - Competência: set/2026 Períodos: 5 - JOADIR MENDES DA SILVA- 05402462127- 104- 3090- 157266939
A38: 1 | B38: JOAO CARLOS DE OLIVEIRA | C38: A | D38: 417.29 | E38: =D38-G38 -> 0 | F38: JOAO CARLOS DE OLIVEIRA | G38: 417.29 | I38: =G38-J38 -> 0 | J38: 417.29 | K38: Emprestimo Consignado - Competência: set/2026 Períodos: 5 - JOAO CARLOS DE OLIVEIRA- 33615374878- 104- 0319- 927463242
... A40: 1 | B40: JOCELINO FERNANDO DA SILVA | C40: A | D40: 514.28 | E40: =D40-G40 -> 0 | F40: JOCELINO FERNANDO DA SILVA | G40: 514.28 | I40: =G40-J40 -> 0 | J40: 514.28 | K40: Emprestimo Consignado - Competência: set/2026 Períodos: 5 - JOCELINO FERNANDO DA SILVA- 70364852135- 104- 3090- 142857227
A41: 1 | B41: JOSE SEBASTIAO DOS SANTOS | C41: D | D41: 3994.47 | E41: =D41-G41 -> 3994.47 | I41: =G41-J41 -> -3994.47 | J41: 3994.47 | K41: Emprestimo Consignado - Competência: set/2026 Períodos: 5 - JOSE SEBASTIAO DOS SANTOS- 81485026415- 104- 3090- 166910497
A42: 1 | B42: JOSE SERGIO DA SILVA | C42: D | D42: 1880.19 | E42: =D42-G42 -> 0 | F42: JOSE SERGIO DA SILVA | G42: 1880.19 | I42: =G42-J42 -> 0 | J42: 1880.19 | K42: Emprestimo Consignado - Competência: set/2026 Períodos: 5 - JOSE SERGIO DA SILVA- 03664054113- 104- 3090- 199843284
A43: 1 | B43: JOSE VALENTIM LEITE | C43: A | D43: 281.18 | E43: =D43-G43 -> 0 | F43: JOSE VALENTIM LEITE | G43: 281.18 | I43: =G43-J43 -> 0 | J43: 281.18 | K43: Emprestimo Consignado - Competência: set/2026 Períodos: 5 - JOSE VALENTIM LEITE- 10026082870- 104- 3090- 154086875
A44: 1 | B44: JOSENILSON ARMANDO DA SILVA | C44: A | D44: 645.66 | E44: =D44-G44 -> 0 | F44: JOSENILSON ARMANDO DA SILVA | G44: 645.66 | I44: =G44-J44 -> 0 | J44: 645.66 | K44: Emprestimo Consignado - Competência: set/2026 Períodos: 5 - JOSENILSON ARMANDO DA SILVA- 06034023130- 104- 3090- 159029616
A45: 1 | B45: JOSIMAR RODRIGUES NOBRES | C45: A | D45: 482 | E45: =D45-G45 -> 0 | F45: JOSIMAR RODRIGUES NOBRES | G45: 482 | I45: =G45-J45 -> 0 | J45: 482 | K45: Emprestimo Consignado - Competência: set/2026 Períodos: 5 - JOSIMAR RODRIGUES NOBRES- 00981190103- 104- 3090- 159029713
...

Sheet EMPRESAS
A1: EMPRESAS
A2: CONCRETA
A3: JPL
A4: JC GOMES
